Workbook

Sheet Inputs
A1: RMBS Interview Model Inputs
A2: Section 1: Pool structure
A3: Initial Pool Balance | B3: =B4*B5 -> 300000000
A4: Loan Count | B4: 1000
A5: Balance Per Loan | B5: 300000
A6: WAC (annual) | B6: 0.0575
A7: Remaining Term (months) | B7: 300
A8: Servicing/Admin Fee (annual) | B8: 0.005
A9: Class A Share | B9: 0.8
A10: Class B Share | B10: 0.15
A11: Equity Share | B11: 0.05
A13: Section 2: V1 scenario
A14: Active Scenario | B14: Base
A15: CPR (annual, active scenario) | B15: =INDEX(Scenarios!B2:B4,MATCH(B14,Scenarios!A2:A4,0)) -> 0.08
A16: CDR (annual, active scenario) | B16: =INDEX(Scenarios!C2:C4,MATCH(B14,Scenarios!A2:A4,0)) -> 0.015
A17: Severity (active scenario) | B17: =INDEX(Scenarios!D2:D4,MATCH(B14,Scenarios!A2:A4,0)) -> 0.25
A18: SMM (monthly) | B18: =1-(1-B15)^(1/12) -> 0.0069243826
A19: MDR (monthly) | B19: =1-(1-B16)^(1/12) -> 0.001258677
A22: Section 3: V2 parameters
A23: V2 Trigger Loss Threshold | B23: 0.03
A24: V2 Trigger DQ Threshold | B24: 0.06
A25: V2 Initial DQ30 Share | B25: 0.01
A26: V2 Initial DQ60 Share | B26: 0.005
A27: V2 Roll to 30 (annual) | B27: =INDEX(Scenarios_V2!D2:D4,MATCH(B14,Scenarios_V2!A2:A4,0)) -> 0.04
A28: V2 Default from 60 (annual) | B28: =INDEX(Scenarios_V2!E2:E4,MATCH(B14,Scenarios_V2!A2:A4,0)) -> 0.1
A29: V2 Cure30 (monthly) | B29: =INDEX(Scenarios_V2!F2:F4,MATCH(B14,Scenarios_V2!A2:A4,0)) -> 0.35
A30: V2 Roll30->60 (monthly) | B30: =INDEX(Scenarios_V2!G2:G4,MATCH(B14,Scenarios_V2!A2:A4,0)) -> 0.2
A31: V2 Cure60 (monthly) | B31: =INDEX(Scenarios_V2!H2:H4,MATCH(B14,Scenarios_V2!A2:A4,0)) -> 0.12
A32: V2 SMM (monthly) | B32: =INDEX(Scenarios_V2!B2:B4,MATCH(B14,Scenarios_V2!A2:A4,0)) -> 0.08
A33: V2 RollTo30 MDR (monthly) | B33: =1-(1-B27)^(1/12) -> 0.0033960532
A34: V2 Default60 MDR (monthly) | B34: =1-(1-B28)^(1/12) -> 0.008741611
A35: V2 Severity (active scenario) | B35: =INDEX(Scenarios_V2!C2:C4,MATCH(B14,Scenarios_V2!A2:A4,0)) -> 0.25
A37: Notes
A38: All downstream formulas should reference these inputs.
A39: Change B12 to Base, Mild_Stress, or Severe_Stress.

Sheet LoanPool
A1: Month | B1: Begin_Balance | C1: Scheduled_Payment | D1: Interest | E1: Scheduled_Principal | F1: Prepayment | G1: Default | H1: Loss | I1: Total_Principal_Outflow | J1: End_Balance | K1: Fee | L1: Interest_Available | M1: Principal_Available
A2: 1 | B2: =Inputs!B3 -> 300000000 | C2: =IF(A2<=Inputs!B7,IF(B2>0,-PMT(Inputs!B6/12,Inputs!B7-A2+1,B2),0),0) -> 1887319.2 | D2: =B2*Inputs!B6/12 -> 1437500 | E2: =MAX(C2-D2,0) -> 449819.21 | F2: =MAX((B2-E2)*Inputs!B18,0) -> 2074200.1 | G2: =MAX((B2-E2-F2)*Inputs!B19,0) -> 374426.18 | H2: =G2*Inputs!B17 -> 93606.545 | I2: =MIN(B2,E2+F2+G2) -> 2898445.5 | J2: =MAX(B2-I2,0) -> 2.9710155e+08 | K2: =B2*Inputs!B8/12 -> 125000 | L2: =MAX(D2-K2,0) -> 1312500 | M2: =MAX(I2-H2,0) -> 2804838.9
A3: 2 | B3: =J2 -> 2.9710155e+08 | C3: =IF(A3<=Inputs!B7,IF(B3>0,-PMT(Inputs!B6/12,Inputs!B7-A3+1,B3),0),0) -> 1871891.6 | D3: =B3*Inputs!B6/12 -> 1423611.6 | E3: =MAX(C3-D3,0) -> 448280 | F3: =MAX((B3-E3)*Inputs!B18,0) -> 2054140.8 | G3: =MAX((B3-E3-F3)*Inputs!B19,0) -> 370805.16 | H3: =G3*Inputs!B17 -> 92701.29 | I3: =MIN(B3,E3+F3+G3) -> 2873225.9 | J3: =MAX(B3-I3,0) -> 2.9422833e+08 | K3: =B3*Inputs!B8/12 -> 123792.31 | L3: =MAX(D3-K3,0) -> 1299819.3 | M3: =MAX(I3-H3,0) -> 2780524.6
A4: 3 | B4: =J3 -> 2.9422833e+08 | C4: =IF(A4<=Inputs!B7,IF(B4>0,-PMT(Inputs!B6/12,Inputs!B7-A4+1,B4),0),0) -> 1856590.1 | D4: =B4*Inputs!B6/12 -> 1409844.1 | E4: =MAX(C4-D4,0) -> 446746.05 | F4: =MAX((B4-E4)*Inputs!B18,0) -> 2034256.1 | G4: =MAX((B4-E4-F4)*Inputs!B19,0) -> 367215.65 | H4: =G4*Inputs!B17 -> 91803.914 | I4: =MIN(B4,E4+F4+G4) -> 2848217.8 | J4: =MAX(B4-I4,0) -> 2.9138011e+08 | K4: =B4*Inputs!B8/12 -> 122595.14 | L4: =MAX(D4-K4,0) -> 1287248.9 | M4: =MAX(I4-H4,0) -> 2756413.9
A5: 4 | B5: =J4 -> 2.9138011e+08 | C5: =IF(A5<=Inputs!B7,IF(B5>0,-PMT(Inputs!B6/12,Inputs!B7-A5+1,B5),0),0) -> 1841413.7 | D5: =B5*Inputs!B6/12 -> 1396196.4 | E5: =MAX(C5-D5,0) -> 445217.35 | F5: =MAX((B5-E5)*Inputs!B18,0) -> 2014544.5 | G5: =MAX((B5-E5-F5)*Inputs!B19,0) -> 363657.4 | H5: =G5*Inputs!B17 -> 90914.351 | I5: =MIN(B5,E5+F5+G5) -> 2823419.3 | J5: =MAX(B5-I5,0) -> 2.8855669e+08 | K5: =B5*Inputs!B8/12 -> 121408.38 | L5: =MAX(D5-K5,0) -> 1274788 | M5: =MAX(I5-H5,0) -> 2732504.9
A6: 5 | B6: =J5 -> 2.8855669e+08 | C6: =IF(A6<=Inputs!B7,IF(B6>0,-PMT(Inputs!B6/12,Inputs!B7-A6+1,B6),0),0) -> 1826361.4 | D6: =B6*Inputs!B6/12 -> 1382667.5 | E6: =MAX(C6-D6,0) -> 443693.89 | F6: =MAX((B6-E6)*Inputs!B18,0) -> 1995004.6 | G6: =MAX((B6-E6-F6)*Inputs!B19,0) -> 360130.14 | H6: =G6*Inputs!B17 -> 90032.536 | I6: =MIN(B6,E6+F6+G6) -> 2798828.7 | J6: =MAX(B6-I6,0) -> 2.8575786e+08 | K6: =B6*Inputs!B8/12 -> 120231.95 | L6: =MAX(D6-K6,0) -> 1262435.5 | M6: =MAX(I6-H6,0) -> 2708796.1
A7: 6 | B7: =J6 -> 2.8575786e+08 | C7: =IF(A7<=Inputs!B7,IF(B7>0,-PMT(Inputs!B6/12,Inputs!B7-A7+1,B7),0),0) -> 1811432.1 | D7: =B7*Inputs!B6/12 -> 1369256.4 | E7: =MAX(C7-D7,0) -> 442175.64 | F7: =MAX((B7-E7)*Inputs!B18,0) -> 1975635 | G7: =MAX((B7-E7-F7)*Inputs!B19,0) -> 356633.61 | H7: =G7*Inputs!B17 -> 89158.403 | I7: =MIN(B7,E7+F7+G7) -> 2774444.2 | J7: =MAX(B7-I7,0) -> 2.8298342e+08 | K7: =B7*Inputs!B8/12 -> 119065.78 | L7: =MAX(D7-K7,0) -> 1250190.7 | M7: =MAX(I7-H7,0) -> 2685285.8
A8: 7 | B8: =J7 -> 2.8298342e+08 | C8: =IF(A8<=Inputs!B7,IF(B8>0,-PMT(Inputs!B6/12,Inputs!B7-A8+1,B8),0),0) -> 1796624.8 | D8: =B8*Inputs!B6/12 -> 1355962.2 | E8: =MAX(C8-D8,0) -> 440662.58 | F8: =MAX((B8-E8)*Inputs!B18,0) -> 1956434.2 | G8: =MAX((B8-E8-F8)*Inputs!B19,0) -> 353167.56 | H8: =G8*Inputs!B17 -> 88291.889 | I8: =MIN(B8,E8+F8+G8) -> 2750264.3 | J8: =MAX(B8-I8,0) -> 2.8023315e+08 | K8: =B8*Inputs!B8/12 -> 117909.76 | L8: =MAX(D8-K8,0) -> 1238052.5 | M8: =MAX(I8-H8,0) -> 2661972.4
A9: 8 | B9: =J8 -> 2.8023315e+08 | C9: =IF(A9<=Inputs!B7,IF(B9>0,-PMT(Inputs!B6/12,Inputs!B7-A9+1,B9),0),0) -> 1781938.6 | D9: =B9*Inputs!B6/12 -> 1342783.9 | E9: =MAX(C9-D9,0) -> 439154.7 | F9: =MAX((B9-E9)*Inputs!B18,0) -> 1937400.7 | G9: =MAX((B9-E9-F9)*Inputs!B19,0) -> 349731.72 | H9: =G9*Inputs!B17 -> 87432.929 | I9: =MIN(B9,E9+F9+G9) -> 2726287.1 | J9: =MAX(B9-I9,0) -> 2.7750687e+08 | K9: =B9*Inputs!B8/12 -> 116763.81 | L9: =MAX(D9-K9,0) -> 1226020.1 | M9: =MAX(I9-H9,0) -> 2638854.2
A10: 9 | B10: =J9 -> 2.7750687e+08 | C10: =IF(A10<=Inputs!B7,IF(B10>0,-PMT(Inputs!B6/12,Inputs!B7-A10+1,B10),0),0) -> 1767372.4 | D10: =B10*Inputs!B6/12 -> 1329720.4 | E10: =MAX(C10-D10,0) -> 437651.98 | F10: =MAX((B10-E10)*Inputs!B18,0) -> 1918533.3 | G10: =MAX((B10-E10-F10)*Inputs!B19,0) -> 346325.84 | H10: =G10*Inputs!B17 -> 86581.46 | I10: =MIN(B10,E10+F10+G10) -> 2702511.1 | J10: =MAX(B10-I10,0) -> 2.7480436e+08 | K10: =B10*Inputs!B8/12 -> 115627.86 | L10: =MAX(D10-K10,0) -> 1214092.5 | M10: =MAX(I10-H10,0) -> 2615929.6
A11: 10 | B11: =J10 -> 2.7480436e+08 | C11: =IF(A11<=Inputs!B7,IF(B11>0,-PMT(Inputs!B6/12,Inputs!B7-A11+1,B11),0),0) -> 1752925.3 | D11: =B11*Inputs!B6/12 -> 1316770.9 | E11: =MAX(C11-D11,0) -> 436154.4 | F11: =MAX((B11-E11)*Inputs!B18,0) -> 1899830.4 | G11: =MAX((B11-E11-F11)*Inputs!B19,0) -> 342949.68 | H11: =G11*Inputs!B17 -> 85737.419 | I11: =MIN(B11,E11+F11+G11) -> 2678934.5 | J11: =MAX(B11-I11,0) -> 2.7212542e+08 | K11: =B11*Inputs!B8/12 -> 114501.82 | L11: =MAX(D11-K11,0) -> 1202269.1 | M11: =MAX(I11-H11,0) -> 2593197.1
A12: 11 | B12: =J11 -> 2.7212542e+08 | C12: =IF(A12<=Inputs!B7,IF(B12>0,-PMT(Inputs!B6/12,Inputs!B7-A12+1,B12),0),0) -> 1738596.3 | D12: =B12*Inputs!B6/12 -> 1303934.3 | E12: =MAX(C12-D12,0) -> 434661.95 | F12: =MAX((B12-E12)*Inputs!B18,0) -> 1881290.8 | G12: =MAX((B12-E12-F12)*Inputs!B19,0) -> 339602.98 | H12: =G12*Inputs!B17 -> 84900.744 | I12: =MIN(B12,E12+F12+G12) -> 2655555.7 | J12: =MAX(B12-I12,0) -> 2.6946987e+08 | K12: =B12*Inputs!B8/12 -> 113385.59 | L12: =MAX(D12-K12,0) -> 1190548.7 | M12: =MAX(I12-H12,0) -> 2570655
A13: 12 | B13: =J12 -> 2.6946987e+08 | C13: =IF(A13<=Inputs!B7,IF(B13>0,-PMT(Inputs!B6/12,Inputs!B7-A13+1,B13),0),0) -> 1724384.4 | D13: =B13*Inputs!B6/12 -> 1291209.8 | E13: =MAX(C13-D13,0) -> 433174.6 | F13: =MAX((B13-E13)*Inputs!B18,0) -> 1862913 | G13: =MAX((B13-E13-F13)*Inputs!B19,0) -> 336285.49 | H13: =G13*Inputs!B17 -> 84071.374 | I13: =MIN(B13,E13+F13+G13) -> 2632373.1 | J13: =MAX(B13-I13,0) -> 2.6683749e+08 | K13: =B13*Inputs!B8/12 -> 112279.11 | L13: =MAX(D13-K13,0) -> 1178930.7 | M13: =MAX(I13-H13,0) -> 2548301.7
A14: 13 | B14: =J13 -> 2.6683749e+08 | C14: =IF(A14<=Inputs!B7,IF(B14>0,-PMT(Inputs!B6/12,Inputs!B7-A14+1,B14),0),0) -> 1710288.7 | D14: =B14*Inputs!B6/12 -> 1278596.3 | E14: =MAX(C14-D14,0) -> 431692.35 | F14: =MAX((B14-E14)*Inputs!B18,0) -> 1844695.7 | G14: =MAX((B14-E14-F14)*Inputs!B19,0) -> 332996.98 | H14: =G14*Inputs!B17 -> 83249.246 | I14: =MIN(B14,E14+F14+G14) -> 2609385 | J14: =MAX(B14-I14,0) -> 2.6422811e+08 | K14: =B14*Inputs!B8/12 -> 111182.29 | L14: =MAX(D14-K14,0) -> 1167414 | M14: =MAX(I14-H14,0) -> 2526135.8
A15: 14 | B15: =J14 -> 2.6422811e+08 | C15: =IF(A15<=Inputs!B7,IF(B15>0,-PMT(Inputs!B6/12,Inputs!B7-A15+1,B15),0),0) -> 1696308.2 | D15: =B15*Inputs!B6/12 -> 1266093 | E15: =MAX(C15-D15,0) -> 430215.16 | F15: =MAX((B15-E15)*Inputs!B18,0) -> 1826637.5 | G15: =MAX((B15-E15-F15)*Inputs!B19,0) -> 329737.2 | H15: =G15*Inputs!B17 -> 82434.3 | I15: =MIN(B15,E15+F15+G15) -> 2586589.9 | J15: =MAX(B15-I15,0) -> 2.6164152e+08 | K15: =B15*Inputs!B8/12 -> 110095.04 | L15: =MAX(D15-K15,0) -> 1155998 | M15: =MAX(I15-H15,0) -> 2504155.6
A16: 15 | B16: =J15 -> 2.6164152e+08 | C16: =IF(A16<=Inputs!B7,IF(B16>0,-PMT(Inputs!B6/12,Inputs!B7-A16+1,B16),0),0) -> 1682442 | D16: =B16*Inputs!B6/12 -> 1253698.9 | E16: =MAX(C16-D16,0) -> 428743.03 | F16: =MAX((B16-E16)*Inputs!B18,0) -> 1808737.2 | G16: =MAX((B16-E16-F16)*Inputs!B19,0) -> 326505.9 | H16: =G16*Inputs!B17 -> 81626.475 | I16: =MIN(B16,E16+F16+G16) -> 2563986.1 | J16: =MAX(B16-I16,0) -> 2.5907753e+08 | K16: =B16*Inputs!B8/12 -> 109017.3 | L16: =MAX(D16-K16,0) -> 1144681.6 | M16: =MAX(I16-H16,0) -> 2482359.7
A17: 16 | B17: =J16 -> 2.5907753e+08 | C17: =IF(A17<=Inputs!B7,IF(B17>0,-PMT(Inputs!B6/12,Inputs!B7-A17+1,B17),0),0) -> 1668689.1 | D17: =B17*Inputs!B6/12 -> 1241413.2 | E17: =MAX(C17-D17,0) -> 427275.94 | F17: =MAX((B17-E17)*Inputs!B18,0) -> 1790993.3 | G17: =MAX((B17-E17-F17)*Inputs!B19,0) -> 323302.85 | H17: =G17*Inputs!B17 -> 80825.713 | I17: =MIN(B17,E17+F17+G17) -> 2541572.1 | J17: =MAX(B17-I17,0) -> 2.5653596e+08 | K17: =B17*Inputs!B8/12 -> 107948.97 | L17: =MAX(D17-K17,0) -> 1133464.2 | M17: =MAX(I17-H17,0) -> 2460746.4
A18: 17 | B18: =J17 -> 2.5653596e+08 | C18: =IF(A18<=Inputs!B7,IF(B18>0,-PMT(Inputs!B6/12,Inputs!B7-A18+1,B18),0),0) -> 1655048.7 | D18: =B18*Inputs!B6/12 -> 1229234.8 | E18: =MAX(C18-D18,0) -> 425813.87 | F18: =MAX((B18-E18)*Inputs!B18,0) -> 1773404.6 | G18: =MAX((B18-E18-F18)*Inputs!B19,0) -> 320127.81 | H18: =G18*Inputs!B17 -> 80031.953 | I18: =MIN(B18,E18+F18+G18) -> 2519346.3 | J18: =MAX(B18-I18,0) -> 2.5401661e+08 | K18: =B18*Inputs!B8/12 -> 106889.98 | L18: =MAX(D18-K18,0) -> 1122344.8 | M18: =MAX(I18-H18,0) -> 2439314.4
A19: 18 | B19: =J18 -> 2.5401661e+08 | C19: =IF(A19<=Inputs!B7,IF(B19>0,-PMT(Inputs!B6/12,Inputs!B7-A19+1,B19),0),0) -> 1641519.7 | D19: =B19*Inputs!B6/12 -> 1217162.9 | E19: =MAX(C19-D19,0) -> 424356.8 | F19: =MAX((B19-E19)*Inputs!B18,0) -> 1755969.8 | G19: =MAX((B19-E19-F19)*Inputs!B19,0) -> 316980.55 | H19: =G19*Inputs!B17 -> 79245.137 | I19: =MIN(B19,E19+F19+G19) -> 2497307.2 | J19: =MAX(B19-I19,0) -> 2.5151931e+08 | K19: =B19*Inputs!B8/12 -> 105840.26 | L19: =MAX(D19-K19,0) -> 1111322.7 | M19: =MAX(I19-H19,0) -> 2418062
A20: 19 | B20: =J19 -> 2.5151931e+08 | C20: =IF(A20<=Inputs!B7,IF(B20>0,-PMT(Inputs!B6/12,Inputs!B7-A20+1,B20),0),0) -> 1628101.4 | D20: =B20*Inputs!B6/12 -> 1205196.7 | E20: =MAX(C20-D20,0) -> 422904.71 | F20: =MAX((B20-E20)*Inputs!B18,0) -> 1738687.6 | G20: =MAX((B20-E20-F20)*Inputs!B19,0) -> 313860.82 | H20: =G20*Inputs!B17 -> 78465.206 | I20: =MIN(B20,E20+F20+G20) -> 2475453.1 | J20: =MAX(B20-I20,0) -> 2.4904385e+08 | K20: =B20*Inputs!B8/12 -> 104799.71 | L20: =MAX(D20-K20,0) -> 1100397 | M20: =MAX(I20-H20,0) -> 2396987.9
A21: 20 | B21: =J20 -> 2.4904385e+08 | C21: =IF(A21<=Inputs!B7,IF(B21>0,-PMT(Inputs!B6/12,Inputs!B7-A21+1,B21),0),0) -> 1614792.7 | D21: =B21*Inputs!B6/12 -> 1193335.1 | E21: =MAX(C21-D21,0) -> 421457.6 | F21: =MAX((B21-E21)*Inputs!B18,0) -> 1721556.6 | G21: =MAX((B21-E21-F21)*Inputs!B19,0) -> 310768.41 | H21: =G21*Inputs!B17 -> 77692.103 | I21: =MIN(B21,E21+F21+G21) -> 2453782.6 | J21: =MAX(B21-I21,0) -> 2.4659007e+08 | K21: =B21*Inputs!B8/12 -> 103768.27 | L21: =MAX(D21-K21,0) -> 1089566.9 | M21: =MAX(I21-H21,0) -> 2376090.5
A22: 21 | B22: =J21 -> 2.4659007e+08 | C22: =IF(A22<=Inputs!B7,IF(B22>0,-PMT(Inputs!B6/12,Inputs!B7-A22+1,B22),0),0) -> 1601592.9 | D22: =B22*Inputs!B6/12 -> 1181577.4 | E22: =MAX(C22-D22,0) -> 420015.43 | F22: =MAX((B22-E22)*Inputs!B18,0) -> 1704575.7 | G22: =MAX((B22-E22-F22)*Inputs!B19,0) -> 307703.08 | H22: =G22*Inputs!B17 -> 76925.77 | I22: =MIN(B22,E22+F22+G22) -> 2432294.2 | J22: =MAX(B22-I22,0) -> 2.4415778e+08 | K22: =B22*Inputs!B8/12 -> 102745.86 | L22: =MAX(D22-K22,0) -> 1078831.6 | M22: =MAX(I22-H22,0) -> 2355368.4
A23: 22 | B23: =J22 -> 2.4415778e+08 | C23: =IF(A23<=Inputs!B7,IF(B23>0,-PMT(Inputs!B6/12,Inputs!B7-A23+1,B23),0),0) -> 1588500.9 | D23: =B23*Inputs!B6/12 -> 1169922.7 | E23: =MAX(C23-D23,0) -> 418578.21 | F23: =MAX((B23-E23)*Inputs!B18,0) -> 1687743.5 | G23: =MAX((B23-E23-F23)*Inputs!B19,0) -> 304664.6 | H23: =G23*Inputs!B17 -> 76166.151 | I23: =MIN(B23,E23+F23+G23) -> 2410986.3 | J23: =MAX(B23-I23,0) -> 2.4174679e+08 | K23: =B23*Inputs!B8/12 -> 101732.41 | L23: =MAX(D23-K23,0) -> 1068190.3 | M23: =MAX(I23-H23,0) -> 2334820.1
A24: 23 | B24: =J23 -> 2.4174679e+08 | C24: =IF(A24<=Inputs!B7,IF(B24>0,-PMT(Inputs!B6/12,Inputs!B7-A24+1,B24),0),0) -> 1575515.9 | D24: =B24*Inputs!B6/12 -> 1158370 | E24: =MAX(C24-D24,0) -> 417145.9 | F24: =MAX((B24-E24)*Inputs!B18,0) -> 1671058.8 | G24: =MAX((B24-E24-F24)*Inputs!B19,0) -> 301652.75 | H24: =G24*Inputs!B17 -> 75413.188 | I24: =MIN(B24,E24+F24+G24) -> 2389857.4 | J24: =MAX(B24-I24,0) -> 2.3935693e+08 | K24: =B24*Inputs!B8/12 -> 100727.83 | L24: =MAX(D24-K24,0) -> 1057642.2 | M24: =MAX(I24-H24,0) -> 2314444.3
A25: 24 | B25: =J24 -> 2.3935693e+08 | C25: =IF(A25<=Inputs!B7,IF(B25>0,-PMT(Inputs!B6/12,Inputs!B7-A25+1,B25),0),0) -> 1562637.1 | D25: =B25*Inputs!B6/12 -> 1146918.6 | E25: =MAX(C25-D25,0) -> 415718.49 | F25: =MAX((B25-E25)*Inputs!B18,0) -> 1654520.4 | G25: =MAX((B25-E25-F25)*Inputs!B19,0) -> 298667.31 | H25: =G25*Inputs!B17 -> 74666.827 | I25: =MIN(B25,E25+F25+G25) -> 2368906.2 | J25: =MAX(B25-I25,0) -> 2.3698803e+08 | K25: =B25*Inputs!B8/12 -> 99732.055 | L25: =MAX(D25-K25,0) -> 1047186.6 | M25: =MAX(I25-H25,0) -> 2294239.4
A26: 25 | B26: =J25 -> 2.3698803e+08 | C26: =IF(A26<=Inputs!B7,IF(B26>0,-PMT(Inputs!B6/12,Inputs!B7-A26+1,B26),0),0) -> 1549863.6 | D26: =B26*Inputs!B6/12 -> 1135567.6 | E26: =MAX(C26-D26,0) -> 414295.96 | F26: =MAX((B26-E26)*Inputs!B18,0) -> 1638127 | G26: =MAX((B26-E26-F26)*Inputs!B19,0) -> 295708.04 | H26: =G26*Inputs!B17 -> 73927.011 | I26: =MIN(B26,E26+F26+G26) -> 2348131 | J26: =MAX(B26-I26,0) -> 2.346399e+08 | K26: =B26*Inputs!B8/12 -> 98745.011 | L26: =MAX(D26-K26,0) -> 1036822.6 | M26: =MAX(I26-H26,0) -> 2274204
A27: 26 | B27: =J26 -> 2.346399e+08 | C27: =IF(A27<=Inputs!B7,IF(B27>0,-PMT(Inputs!B6/12,Inputs!B7-A27+1,B27),0),0) -> 1537194.5 | D27: =B27*Inputs!B6/12 -> 1124316.2 | E27: =MAX(C27-D27,0) -> 412878.31 | F27: =MAX((B27-E27)*Inputs!B18,0) -> 1621877.5 | G27: =MAX((B27-E27-F27)*Inputs!B19,0) -> 292774.74 | H27: =G27*Inputs!B17 -> 73193.686 | I27: =MIN(B27,E27+F27+G27) -> 2327530.5 | J27: =MAX(B27-I27,0) -> 2.3231236e+08 | K27: =B27*Inputs!B8/12 -> 97766.623 | L27: =MAX(D27-K27,0) -> 1026549.5 | M27: =MAX(I27-H27,0) -> 2254336.9
A28: 27 | B28: =J27 -> 2.3231236e+08 | C28: =IF(A28<=Inputs!B7,IF(B28>0,-PMT(Inputs!B6/12,Inputs!B7-A28+1,B28),0),0) -> 1524628.9 | D28: =B28*Inputs!B6/12 -> 1113163.4 | E28: =MAX(C28-D28,0) -> 411465.5 | F28: =MAX((B28-E28)*Inputs!B18,0) -> 1605770.6 | G28: =MAX((B28-E28-F28)*Inputs!B19,0) -> 289867.19 | H28: =G28*Inputs!B17 -> 72466.797 | I28: =MIN(B28,E28+F28+G28) -> 2307103.2 | J28: =MAX(B28-I28,0) -> 2.3000526e+08 | K28: =B28*Inputs!B8/12 -> 96796.819 | L28: =MAX(D28-K28,0) -> 1016366.6 | M28: =MAX(I28-H28,0) -> 2234636.4
A29: 28 | B29: =J28 -> 2.3000526e+08 | C29: =IF(A29<=Inputs!B7,IF(B29>0,-PMT(Inputs!B6/12,Inputs!B7-A29+1,B29),0),0) -> 1512166.1 | D29: =B29*Inputs!B6/12 -> 1102108.5 | E29: =MAX(C29-D29,0) -> 410057.53 | F29: =MAX((B29-E29)*Inputs!B18,0) -> 1589805 | G29: =MAX((B29-E29-F29)*Inputs!B19,0) -> 286985.16 | H29: =G29*Inputs!B17 -> 71746.289 | I29: =MIN(B29,E29+F29+G29) -> 2286847.7 | J29: =MAX(B29-I29,0) -> 2.2771841e+08 | K29: =B29*Inputs!B8/12 -> 95835.526 | L29: =MAX(D29-K29,0) -> 1006273 | M29: =MAX(I29-H29,0) -> 2215101.4
A30: 29 | B30: =J29 -> 2.2771841e+08 | C30: =IF(A30<=Inputs!B7,IF(B30>0,-PMT(Inputs!B6/12,Inputs!B7-A30+1,B30),0),0) -> 1499805.1 | D30: =B30*Inputs!B6/12 -> 1091150.7 | E30: =MAX(C30-D30,0) -> 408654.37 | F30: =MAX((B30-E30)*Inputs!B18,0) -> 1573979.7 | G30: =MAX((B30-E30-F30)*Inputs!B19,0) -> 284128.44 | H30: =G30*Inputs!B17 -> 71032.11 | I30: =MIN(B30,E30+F30+G30) -> 2266762.6 | J30: =MAX(B30-I30,0) -> 2.2545165e+08 | K30: =B30*Inputs!B8/12 -> 94882.672 | L30: =MAX(D30-K30,0) -> 996268.06 | M30: =MAX(I30-H30,0) -> 2195730.5
A31: 30 | B31: =J30 -> 2.2545165e+08 | C31: =IF(A31<=Inputs!B7,IF(B31>0,-PMT(Inputs!B6/12,Inputs!B7-A31+1,B31),0),0) -> 1487545.2 | D31: =B31*Inputs!B6/12 -> 1080289.2 | E31: =MAX(C31-D31,0) -> 407256.02 | F31: =MAX((B31-E31)*Inputs!B18,0) -> 1558293.5 | G31: =MAX((B31-E31-F31)*Inputs!B19,0) -> 281296.82 | H31: =G31*Inputs!B17 -> 70324.205 | I31: =MIN(B31,E31+F31+G31) -> 2246846.3 | J31: =MAX(B31-I31,0) -> 2.232048e+08 | K31: =B31*Inputs!B8/12 -> 93938.188 | L31: =MAX(D31-K31,0) -> 986350.97 | M31: =MAX(I31-H31,0) -> 2176522.1
A32: 31 | B32: =J31 -> 2.232048e+08 | C32: =IF(A32<=Inputs!B7,IF(B32>0,-PMT(Inputs!B6/12,Inputs!B7-A32+1,B32),0),0) -> 1475385.5 | D32: =B32*Inputs!B6/12 -> 1069523 | E32: =MAX(C32-D32,0) -> 405862.45 | F32: =MAX((B32-E32)*Inputs!B18,0) -> 1542745.1 | G32: =MAX((B32-E32-F32)*Inputs!B19,0) -> 278490.09 | H32: =G32*Inputs!B17 -> 69622.523 | I32: =MIN(B32,E32+F32+G32) -> 2227097.7 | J32: =MAX(B32-I32,0) -> 2.2097771e+08 | K32: =B32*Inputs!B8/12 -> 93002.002 | L32: =MAX(D32-K32,0) -> 976521.02 | M32: =MAX(I32-H32,0) -> 2157475.1
A33: 32 | B33: =J32 -> 2.2097771e+08 | C33: =IF(A33<=Inputs!B7,IF(B33>0,-PMT(Inputs!B6/12,Inputs!B7-A33+1,B33),0),0) -> 1463325.2 | D33: =B33*Inputs!B6/12 -> 1058851.5 | E33: =MAX(C33-D33,0) -> 404473.66 | F33: =MAX((B33-E33)*Inputs!B18,0) -> 1527333.5 | G33: =MAX((B33-E33-F33)*Inputs!B19,0) -> 275708.04 | H33: =G33*Inputs!B17 -> 68927.01 | I33: =MIN(B33,E33+F33+G33) -> 2207515.2 | J33: =MAX(B33-I33,0) -> 2.1877019e+08 | K33: =B33*Inputs!B8/12 -> 92074.045 | L33: =MAX(D33-K33,0) -> 966777.47 | M33: =MAX(I33-H33,0) -> 2138588.2
A34: 33 | B34: =J33 -> 2.1877019e+08 | C34: =IF(A34<=Inputs!B7,IF(B34>0,-PMT(Inputs!B6/12,Inputs!B7-A34+1,B34),0),0) -> 1451363.4 | D34: =B34*Inputs!B6/12 -> 1048273.8 | E34: =MAX(C34-D34,0) -> 403089.61 | F34: =MAX((B34-E34)*Inputs!B18,0) -> 1512057.4 | G34: =MAX((B34-E34-F34)*Inputs!B19,0) -> 272950.46 | H34: =G34*Inputs!B17 -> 68237.615 | I34: =MIN(B34,E34+F34+G34) -> 2188097.4 | J34: =MAX(B34-I34,0) -> 2.1658209e+08 | K34: =B34*Inputs!B8/12 -> 91154.247 | L34: =MAX(D34-K34,0) -> 957119.59 | M34: =MAX(I34-H34,0) -> 2119859.8
A35: 34 | B35: =J34 -> 2.1658209e+08 | C35: =IF(A35<=Inputs!B7,IF(B35>0,-PMT(Inputs!B6/12,Inputs!B7-A35+1,B35),0),0) -> 1439499.5 | D35: =B35*Inputs!B6/12 -> 1037789.2 | E35: =MAX(C35-D35,0) -> 401710.3 | F35: =MAX((B35-E35)*Inputs!B18,0) -> 1496915.7 | G35: =MAX((B35-E35-F35)*Inputs!B19,0) -> 270217.15 | H35: =G35*Inputs!B17 -> 67554.287 | I35: =MIN(B35,E35+F35+G35) -> 2168843.1 | J35: =MAX(B35-I35,0) -> 2.1441325e+08 | K35: =B35*Inputs!B8/12 -> 90242.539 | L35: =MAX(D35-K35,0) -> 947546.66 | M35: =MAX(I35-H35,0) -> 2101288.9
A36: 35 | B36: =J35 -> 2.1441325e+08 | C36: =IF(A36<=Inputs!B7,IF(B36>0,-PMT(Inputs!B6/12,Inputs!B7-A36+1,B36),0),0) -> 1427732.5 | D36: =B36*Inputs!B6/12 -> 1027396.8 | E36: =MAX(C36-D36,0) -> 400335.71 | F36: =MAX((B36-E36)*Inputs!B18,0) -> 1481907.3 | G36: =MAX((B36-E36-F36)*Inputs!B19,0) -> 267507.9 | H36: =G36*Inputs!B17 -> 66876.974 | I36: =MIN(B36,E36+F36+G36) -> 2149750.9 | J36: =MAX(B36-I36,0) -> 2.122635e+08 | K36: =B36*Inputs!B8/12 -> 89338.855 | L36: =MAX(D36-K36,0) -> 938057.98 | M36: =MAX(I36-H36,0) -> 2082873.9
A37: 36 | B37: =J36 -> 2.122635e+08 | C37: =IF(A37<=Inputs!B7,IF(B37>0,-PMT(Inputs!B6/12,Inputs!B7-A37+1,B37),0),0) -> 1416061.8 | D37: =B37*Inputs!B6/12 -> 1017095.9 | E37: =MAX(C37-D37,0) -> 398965.82 | F37: =MAX((B37-E37)*Inputs!B18,0) -> 1467031.1 | G37: =MAX((B37-E37-F37)*Inputs!B19,0) -> 264822.5 | H37: =G37*Inputs!B17 -> 66205.626 | I37: =MIN(B37,E37+F37+G37) -> 2130819.4 | J37: =MAX(B37-I37,0) -> 2.1013268e+08 | K37: =B37*Inputs!B8/12 -> 88443.125 | L37: =MAX(D37-K37,0) -> 928652.82 | M37: =MAX(I37-H37,0) -> 2064613.8
A38: 37 | B38: =J37 -> 2.1013268e+08 | C38: =IF(A38<=Inputs!B7,IF(B38>0,-PMT(Inputs!B6/12,Inputs!B7-A38+1,B38),0),0) -> 1404486.4 | D38: =B38*Inputs!B6/12 -> 1006885.8 | E38: =MAX(C38-D38,0) -> 397600.62 | F38: =MAX((B38-E38)*Inputs!B18,0) -> 1452285.9 | G38: =MAX((B38-E38-F38)*Inputs!B19,0) -> 262160.77 | H38: =G38*Inputs!B17 -> 65540.192 | I38: =MIN(B38,E38+F38+G38) -> 2112047.3 | J38: =MAX(B38-I38,0) -> 2.0802063e+08 | K38: =B38*Inputs!B8/12 -> 87555.284 | L38: =MAX(D38-K38,0) -> 919330.48 | M38: =MAX(I38-H38,0) -> 2046507.1
A39: 38 | B39: =J38 -> 2.0802063e+08 | C39: =IF(A39<=Inputs!B7,IF(B39>0,-PMT(Inputs!B6/12,Inputs!B7-A39+1,B39),0),0) -> 1393005.6 | D39: =B39*Inputs!B6/12 -> 996765.54 | E39: =MAX(C39-D39,0) -> 396240.09 | F39: =MAX((B39-E39)*Inputs!B18,0) -> 1437670.7 | G39: =MAX((B39-E39-F39)*Inputs!B19,0) -> 259522.49 | H39: =G39*Inputs!B17 -> 64880.622 | I39: =MIN(B39,E39+F39+G39) -> 2093433.3 | J39: =MAX(B39-I39,0) -> 2.059272e+08 | K39: =B39*Inputs!B8/12 -> 86675.264 | L39: =MAX(D39-K39,0) -> 910090.27 | M39: =MAX(I39-H39,0) -> 2028552.7
A40: 39 | B40: =J39 -> 2.059272e+08 | C40: =IF(A40<=Inputs!B7,IF(B40>0,-PMT(Inputs!B6/12,Inputs!B7-A40+1,B40),0),0) -> 1381618.7 | D40: =B40*Inputs!B6/12 -> 986734.5 | E40: =MAX(C40-D40,0) -> 394884.22 | F40: =MAX((B40-E40)*Inputs!B18,0) -> 1423184.4 | G40: =MAX((B40-E40-F40)*Inputs!B19,0) -> 256907.47 | H40: =G40*Inputs!B17 -> 64226.868 | I40: =MIN(B40,E40+F40+G40) -> 2074976.1 | J40: =MAX(B40-I40,0) -> 2.0385222e+08 | K40: =B40*Inputs!B8/12 -> 85803 | L40: =MAX(D40-K40,0) -> 900931.5 | M40: =MAX(I40-H40,0) -> 2010749.2
...

Sheet Waterfall
A1: Month | B1: Pool_Interest_Available | C1: Pool_Principal_Available | D1: Pool_Loss | E1: A_Begin | F1: B_Begin | G1: E_Begin | H1: Loss_to_E | I1: Loss_to_B | J1: Loss_to_A | K1: A_After_Loss | L1: B_After_Loss | M1: E_After_Loss | N1: A_Int_Due | O1: A_Int_Paid | P1: A_Int_Shortfall | Q1: B_Int_Due | R1: B_Int_Paid | S1: B_Int_Shortfall | T1: E_Residual_Int | U1: A_Principal_Paid | V1: B_Principal_Paid | W1: E_Principal_Paid | X1: A_End | Y1: B_End | Z1: E_End | AA1: Principal_Diff | AB1: Interest_Diff | AC1: Loss_Diff
A2: 1 | B2: =LoanPool!L2 -> 1312500 | C2: =LoanPool!M2 -> 2804838.9 | D2: =LoanPool!H2 -> 93606.545 | E2: =Inputs!B3*Inputs!B9 -> 240000000 | F2: =Inputs!B3*Inputs!B10 -> 45000000 | G2: =Inputs!B3*Inputs!B11 -> 15000000 | H2: =MIN(D2,G2) -> 93606.545 | I2: =MIN(MAX(D2-H2,0),F2) -> 0 | J2: =MIN(MAX(D2-H2-I2,0),E2) -> 0 | K2: =MAX(E2-J2,0) -> 240000000 | L2: =MAX(F2-I2,0) -> 45000000 | M2: =MAX(G2-H2,0) -> 14906393 | N2: =K2*Inputs!B6/12 -> 1150000 | O2: =MIN(B2,N2) -> 1150000 | P2: =N2-O2 -> 0 | Q2: =L2*Inputs!B6/12 -> 215625 | R2: =MIN(MAX(B2-O2,0),Q2) -> 162500 | S2: =Q2-R2 -> 53125 | T2: =MAX(B2-O2-R2,0) -> 0 | U2: =MIN(C2,K2) -> 2804838.9 | V2: =MIN(MAX(C2-U2,0),L2) -> 0 | W2: =MIN(MAX(C2-U2-V2,0),M2) -> 0 | X2: =MAX(K2-U2,0) -> 2.3719516e+08 | Y2: =MAX(L2-V2,0) -> 45000000 | Z2: =MAX(M2-W2,0) -> 14906393 | AA2: =C2-(U2+V2+W2) -> 0 | AB2: =B2-(O2+R2+T2) -> 0 | AC2: =D2-(H2+I2+J2) -> 0
A3: 2 | B3: =LoanPool!L3 -> 1299819.3 | C3: =LoanPool!M3 -> 2780524.6 | D3: =LoanPool!H3 -> 92701.29 | E3: =X2 -> 2.3719516e+08 | F3: =Y2 -> 45000000 | G3: =Z2 -> 14906393 | H3: =MIN(D3,G3) -> 92701.29 | I3: =MIN(MAX(D3-H3,0),F3) -> 0 | J3: =MIN(MAX(D3-H3-I3,0),E3) -> 0 | K3: =MAX(E3-J3,0) -> 2.3719516e+08 | L3: =MAX(F3-I3,0) -> 45000000 | M3: =MAX(G3-H3,0) -> 14813692 | N3: =K3*Inputs!B6/12 -> 1136560.1 | O3: =MIN(B3,N3) -> 1136560.1 | P3: =N3-O3 -> 0 | Q3: =L3*Inputs!B6/12 -> 215625 | R3: =MIN(MAX(B3-O3,0),Q3) -> 163259.15 | S3: =Q3-R3 -> 52365.846 | T3: =MAX(B3-O3-R3,0) -> 0 | U3: =MIN(C3,K3) -> 2780524.6 | V3: =MIN(MAX(C3-U3,0),L3) -> 0 | W3: =MIN(MAX(C3-U3-V3,0),M3) -> 0 | X3: =MAX(K3-U3,0) -> 2.3441464e+08 | Y3: =MAX(L3-V3,0) -> 45000000 | Z3: =MAX(M3-W3,0) -> 14813692 | AA3: =C3-(U3+V3+W3) -> 0 | AB3: =B3-(O3+R3+T3) -> 0 | AC3: =D3-(H3+I3+J3) -> 0
A4: 3 | B4: =LoanPool!L4 -> 1287248.9 | C4: =LoanPool!M4 -> 2756413.9 | D4: =LoanPool!H4 -> 91803.914 | E4: =X3 -> 2.3441464e+08 | F4: =Y3 -> 45000000 | G4: =Z3 -> 14813692 | H4: =MIN(D4,G4) -> 91803.914 | I4: =MIN(MAX(D4-H4,0),F4) -> 0 | J4: =MIN(MAX(D4-H4-I4,0),E4) -> 0 | K4: =MAX(E4-J4,0) -> 2.3441464e+08 | L4: =MAX(F4-I4,0) -> 45000000 | M4: =MAX(G4-H4,0) -> 14721888 | N4: =K4*Inputs!B6/12 -> 1123236.8 | O4: =MIN(B4,N4) -> 1123236.8 | P4: =N4-O4 -> 0 | Q4: =L4*Inputs!B6/12 -> 215625 | R4: =MIN(MAX(B4-O4,0),Q4) -> 164012.14 | S4: =Q4-R4 -> 51612.862 | T4: =MAX(B4-O4-R4,0) -> 0 | U4: =MIN(C4,K4) -> 2756413.9 | V4: =MIN(MAX(C4-U4,0),L4) -> 0 | W4: =MIN(MAX(C4-U4-V4,0),M4) -> 0 | X4: =MAX(K4-U4,0) -> 2.3165822e+08 | Y4: =MAX(L4-V4,0) -> 45000000 | Z4: =MAX(M4-W4,0) -> 14721888 | AA4: =C4-(U4+V4+W4) -> 0 | AB4: =B4-(O4+R4+T4) -> 0 | AC4: =D4-(H4+I4+J4) -> 0
A5: 4 | B5: =LoanPool!L5 -> 1274788 | C5: =LoanPool!M5 -> 2732504.9 | D5: =LoanPool!H5 -> 90914.351 | E5: =X4 -> 2.3165822e+08 | F5: =Y4 -> 45000000 | G5: =Z4 -> 14721888 | H5: =MIN(D5,G5) -> 90914.351 | I5: =MIN(MAX(D5-H5,0),F5) -> 0 | J5: =MIN(MAX(D5-H5-I5,0),E5) -> 0 | K5: =MAX(E5-J5,0) -> 2.3165822e+08 | L5: =MAX(F5-I5,0) -> 45000000 | M5: =MAX(G5-H5,0) -> 14630974 | N5: =K5*Inputs!B6/12 -> 1110029 | O5: =MIN(B5,N5) -> 1110029 | P5: =N5-O5 -> 0 | Q5: =L5*Inputs!B6/12 -> 215625 | R5: =MIN(MAX(B5-O5,0),Q5) -> 164759 | S5: =Q5-R5 -> 50865.998 | T5: =MAX(B5-O5-R5,0) -> 0 | U5: =MIN(C5,K5) -> 2732504.9 | V5: =MIN(MAX(C5-U5,0),L5) -> 0 | W5: =MIN(MAX(C5-U5-V5,0),M5) -> 0 | X5: =MAX(K5-U5,0) -> 2.2892572e+08 | Y5: =MAX(L5-V5,0) -> 45000000 | Z5: =MAX(M5-W5,0) -> 14630974 | AA5: =C5-(U5+V5+W5) -> 0 | AB5: =B5-(O5+R5+T5) -> 0 | AC5: =D5-(H5+I5+J5) -> 0
A6: 5 | B6: =LoanPool!L6 -> 1262435.5 | C6: =LoanPool!M6 -> 2708796.1 | D6: =LoanPool!H6 -> 90032.536 | E6: =X5 -> 2.2892572e+08 | F6: =Y5 -> 45000000 | G6: =Z5 -> 14630974 | H6: =MIN(D6,G6) -> 90032.536 | I6: =MIN(MAX(D6-H6,0),F6) -> 0 | J6: =MIN(MAX(D6-H6-I6,0),E6) -> 0 | K6: =MAX(E6-J6,0) -> 2.2892572e+08 | L6: =MAX(F6-I6,0) -> 45000000 | M6: =MAX(G6-H6,0) -> 14540941 | N6: =K6*Inputs!B6/12 -> 1096935.7 | O6: =MIN(B6,N6) -> 1096935.7 | P6: =N6-O6 -> 0 | Q6: =L6*Inputs!B6/12 -> 215625 | R6: =MIN(MAX(B6-O6,0),Q6) -> 165499.8 | S6: =Q6-R6 -> 50125.205 | T6: =MAX(B6-O6-R6,0) -> 0 | U6: =MIN(C6,K6) -> 2708796.1 | V6: =MIN(MAX(C6-U6,0),L6) -> 0 | W6: =MIN(MAX(C6-U6-V6,0),M6) -> 0 | X6: =MAX(K6-U6,0) -> 2.2621692e+08 | Y6: =MAX(L6-V6,0) -> 45000000 | Z6: =MAX(M6-W6,0) -> 14540941 | AA6: =C6-(U6+V6+W6) -> 0 | AB6: =B6-(O6+R6+T6) -> 0 | AC6: =D6-(H6+I6+J6) -> 0
A7: 6 | B7: =LoanPool!L7 -> 1250190.7 | C7: =LoanPool!M7 -> 2685285.8 | D7: =LoanPool!H7 -> 89158.403 | E7: =X6 -> 2.2621692e+08 | F7: =Y6 -> 45000000 | G7: =Z6 -> 14540941 | H7: =MIN(D7,G7) -> 89158.403 | I7: =MIN(MAX(D7-H7,0),F7) -> 0 | J7: =MIN(MAX(D7-H7-I7,0),E7) -> 0 | K7: =MAX(E7-J7,0) -> 2.2621692e+08 | L7: =MAX(F7-I7,0) -> 45000000 | M7: =MAX(G7-H7,0) -> 14451783 | N7: =K7*Inputs!B6/12 -> 1083956.1 | O7: =MIN(B7,N7) -> 1083956.1 | P7: =N7-O7 -> 0 | Q7: =L7*Inputs!B6/12 -> 215625 | R7: =MIN(MAX(B7-O7,0),Q7) -> 166234.57 | S7: =Q7-R7 -> 49390.432 | T7: =MAX(B7-O7-R7,0) -> 0 | U7: =MIN(C7,K7) -> 2685285.8 | V7: =MIN(MAX(C7-U7,0),L7) -> 0 | W7: =MIN(MAX(C7-U7-V7,0),M7) -> 0 | X7: =MAX(K7-U7,0) -> 2.2353164e+08 | Y7: =MAX(L7-V7,0) -> 45000000 | Z7: =MAX(M7-W7,0) -> 14451783 | AA7: =C7-(U7+V7+W7) -> 0 | AB7: =B7-(O7+R7+T7) -> 0 | AC7: =D7-(H7+I7+J7) -> 0
A8: 7 | B8: =LoanPool!L8 -> 1238052.5 | C8: =LoanPool!M8 -> 2661972.4 | D8: =LoanPool!H8 -> 88291.889 | E8: =X7 -> 2.2353164e+08 | F8: =Y7 -> 45000000 | G8: =Z7 -> 14451783 | H8: =MIN(D8,G8) -> 88291.889 | I8: =MIN(MAX(D8-H8,0),F8) -> 0 | J8: =MIN(MAX(D8-H8-I8,0),E8) -> 0 | K8: =MAX(E8-J8,0) -> 2.2353164e+08 | L8: =MAX(F8-I8,0) -> 45000000 | M8: =MAX(G8-H8,0) -> 14363491 | N8: =K8*Inputs!B6/12 -> 1071089.1 | O8: =MIN(B8,N8) -> 1071089.1 | P8: =N8-O8 -> 0 | Q8: =L8*Inputs!B6/12 -> 215625 | R8: =MIN(MAX(B8-O8,0),Q8) -> 166963.37 | S8: =Q8-R8 -> 48661.631 | T8: =MAX(B8-O8-R8,0) -> 0 | U8: =MIN(C8,K8) -> 2661972.4 | V8: =MIN(MAX(C8-U8,0),L8) -> 0 | W8: =MIN(MAX(C8-U8-V8,0),M8) -> 0 | X8: =MAX(K8-U8,0) -> 2.2086966e+08 | Y8: =MAX(L8-V8,0) -> 45000000 | Z8: =MAX(M8-W8,0) -> 14363491 | AA8: =C8-(U8+V8+W8) -> 0 | AB8: =B8-(O8+R8+T8) -> 0 | AC8: =D8-(H8+I8+J8) -> 0
A9: 8 | B9: =LoanPool!L9 -> 1226020.1 | C9: =LoanPool!M9 -> 2638854.2 | D9: =LoanPool!H9 -> 87432.929 | E9: =X8 -> 2.2086966e+08 | F9: =Y8 -> 45000000 | G9: =Z8 -> 14363491 | H9: =MIN(D9,G9) -> 87432.929 | I9: =MIN(MAX(D9-H9,0),F9) -> 0 | J9: =MIN(MAX(D9-H9-I9,0),E9) -> 0 | K9: =MAX(E9-J9,0) -> 2.2086966e+08 | L9: =MAX(F9-I9,0) -> 45000000 | M9: =MAX(G9-H9,0) -> 14276058 | N9: =K9*Inputs!B6/12 -> 1058333.8 | O9: =MIN(B9,N9) -> 1058333.8 | P9: =N9-O9 -> 0 | Q9: =L9*Inputs!B6/12 -> 215625 | R9: =MIN(MAX(B9-O9,0),Q9) -> 167686.25 | S9: =Q9-R9 -> 47938.753 | T9: =MAX(B9-O9-R9,0) -> 0 | U9: =MIN(C9,K9) -> 2638854.2 | V9: =MIN(MAX(C9-U9,0),L9) -> 0 | W9: =MIN(MAX(C9-U9-V9,0),M9) -> 0 | X9: =MAX(K9-U9,0) -> 2.1823081e+08 | Y9: =MAX(L9-V9,0) -> 45000000 | Z9: =MAX(M9-W9,0) -> 14276058 | AA9: =C9-(U9+V9+W9) -> 0 | AB9: =B9-(O9+R9+T9) -> 0 | AC9: =D9-(H9+I9+J9) -> 0
A10: 9 | B10: =LoanPool!L10 -> 1214092.5 | C10: =LoanPool!M10 -> 2615929.6 | D10: =LoanPool!H10 -> 86581.46 | E10: =X9 -> 2.1823081e+08 | F10: =Y9 -> 45000000 | G10: =Z9 -> 14276058 | H10: =MIN(D10,G10) -> 86581.46 | I10: =MIN(MAX(D10-H10,0),F10) -> 0 | J10: =MIN(MAX(D10-H10-I10,0),E10) -> 0 | K10: =MAX(E10-J10,0) -> 2.1823081e+08 | L10: =MAX(F10-I10,0) -> 45000000 | M10: =MAX(G10-H10,0) -> 14189477 | N10: =K10*Inputs!B6/12 -> 1045689.3 | O10: =MIN(B10,N10) -> 1045689.3 | P10: =N10-O10 -> 0 | Q10: =L10*Inputs!B6/12 -> 215625 | R10: =MIN(MAX(B10-O10,0),Q10) -> 168403.25 | S10: =Q10-R10 -> 47221.749 | T10: =MAX(B10-O10-R10,0) -> 0 | U10: =MIN(C10,K10) -> 2615929.6 | V10: =MIN(MAX(C10-U10,0),L10) -> 0 | W10: =MIN(MAX(C10-U10-V10,0),M10) -> 0 | X10: =MAX(K10-U10,0) -> 2.1561488e+08 | Y10: =MAX(L10-V10,0) -> 45000000 | Z10: =MAX(M10-W10,0) -> 14189477 | AA10: =C10-(U10+V10+W10) -> 0 | AB10: =B10-(O10+R10+T10) -> 0 | AC10: =D10-(H10+I10+J10) -> 0
A11: 10 | B11: =LoanPool!L11 -> 1202269.1 | C11: =LoanPool!M11 -> 2593197.1 | D11: =LoanPool!H11 -> 85737.419 | E11: =X10 -> 2.1561488e+08 | F11: =Y10 -> 45000000 | G11: =Z10 -> 14189477 | H11: =MIN(D11,G11) -> 85737.419 | I11: =MIN(MAX(D11-H11,0),F11) -> 0 | J11: =MIN(MAX(D11-H11-I11,0),E11) -> 0 | K11: =MAX(E11-J11,0) -> 2.1561488e+08 | L11: =MAX(F11-I11,0) -> 45000000 | M11: =MAX(G11-H11,0) -> 14103739 | N11: =K11*Inputs!B6/12 -> 1033154.6 | O11: =MIN(B11,N11) -> 1033154.6 | P11: =N11-O11 -> 0 | Q11: =L11*Inputs!B6/12 -> 215625 | R11: =MIN(MAX(B11-O11,0),Q11) -> 169114.43 | S11: =Q11-R11 -> 46510.573 | T11: =MAX(B11-O11-R11,0) -> 0 | U11: =MIN(C11,K11) -> 2593197.1 | V11: =MIN(MAX(C11-U11,0),L11) -> 0 | W11: =MIN(MAX(C11-U11-V11,0),M11) -> 0 | X11: =MAX(K11-U11,0) -> 2.1302168e+08 | Y11: =MAX(L11-V11,0) -> 45000000 | Z11: =MAX(M11-W11,0) -> 14103739 | AA11: =C11-(U11+V11+W11) -> 0 | AB11: =B11-(O11+R11+T11) -> 0 | AC11: =D11-(H11+I11+J11) -> 0
A12: 11 | B12: =LoanPool!L12 -> 1190548.7 | C12: =LoanPool!M12 -> 2570655 | D12: =LoanPool!H12 -> 84900.744 | E12: =X11 -> 2.1302168e+08 | F12: =Y11 -> 45000000 | G12: =Z11 -> 14103739 | H12: =MIN(D12,G12) -> 84900.744 | I12: =MIN(MAX(D12-H12,0),F12) -> 0 | J12: =MIN(MAX(D12-H12-I12,0),E12) -> 0 | K12: =MAX(E12-J12,0) -> 2.1302168e+08 | L12: =MAX(F12-I12,0) -> 45000000 | M12: =MAX(G12-H12,0) -> 14018839 | N12: =K12*Inputs!B6/12 -> 1020728.9 | O12: =MIN(B12,N12) -> 1020728.9 | P12: =N12-O12 -> 0 | Q12: =L12*Inputs!B6/12 -> 215625 | R12: =MIN(MAX(B12-O12,0),Q12) -> 169819.82 | S12: =Q12-R12 -> 45805.175 | T12: =MAX(B12-O12-R12,0) -> 0 | U12: =MIN(C12,K12) -> 2570655 | V12: =MIN(MAX(C12-U12,0),L12) -> 0 | W12: =MIN(MAX(C12-U12-V12,0),M12) -> 0 | X12: =MAX(K12-U12,0) -> 2.1045103e+08 | Y12: =MAX(L12-V12,0) -> 45000000 | Z12: =MAX(M12-W12,0) -> 14018839 | AA12: =C12-(U12+V12+W12) -> 0 | AB12: =B12-(O12+R12+T12) -> 0 | AC12: =D12-(H12+I12+J12) -> 0
A13: 12 | B13: =LoanPool!L13 -> 1178930.7 | C13: =LoanPool!M13 -> 2548301.7 | D13: =LoanPool!H13 -> 84071.374 | E13: =X12 -> 2.1045103e+08 | F13: =Y12 -> 45000000 | G13: =Z12 -> 14018839 | H13: =MIN(D13,G13) -> 84071.374 | I13: =MIN(MAX(D13-H13,0),F13) -> 0 | J13: =MIN(MAX(D13-H13-I13,0),E13) -> 0 | K13: =MAX(E13-J13,0) -> 2.1045103e+08 | L13: =MAX(F13-I13,0) -> 45000000 | M13: =MAX(G13-H13,0) -> 13934767 | N13: =K13*Inputs!B6/12 -> 1008411.2 | O13: =MIN(B13,N13) -> 1008411.2 | P13: =N13-O13 -> 0 | Q13: =L13*Inputs!B6/12 -> 215625 | R13: =MIN(MAX(B13-O13,0),Q13) -> 170519.49 | S13: =Q13-R13 -> 45105.51 | T13: =MAX(B13-O13-R13,0) -> 0 | U13: =MIN(C13,K13) -> 2548301.7 | V13: =MIN(MAX(C13-U13,0),L13) -> 0 | W13: =MIN(MAX(C13-U13-V13,0),M13) -> 0 | X13: =MAX(K13-U13,0) -> 2.0790273e+08 | Y13: =MAX(L13-V13,0) -> 45000000 | Z13: =MAX(M13-W13,0) -> 13934767 | AA13: =C13-(U13+V13+W13) -> 0 | AB13: =B13-(O13+R13+T13) -> 0 | AC13: =D13-(H13+I13+J13) -> 0
A14: 13 | B14: =LoanPool!L14 -> 1167414 | C14: =LoanPool!M14 -> 2526135.8 | D14: =LoanPool!H14 -> 83249.246 | E14: =X13 -> 2.0790273e+08 | F14: =Y13 -> 45000000 | G14: =Z13 -> 13934767 | H14: =MIN(D14,G14) -> 83249.246 | I14: =MIN(MAX(D14-H14,0),F14) -> 0 | J14: =MIN(MAX(D14-H14-I14,0),E14) -> 0 | K14: =MAX(E14-J14,0) -> 2.0790273e+08 | L14: =MAX(F14-I14,0) -> 45000000 | M14: =MAX(G14-H14,0) -> 13851518 | N14: =K14*Inputs!B6/12 -> 996200.56 | O14: =MIN(B14,N14) -> 996200.56 | P14: =N14-O14 -> 0 | Q14: =L14*Inputs!B6/12 -> 215625 | R14: =MIN(MAX(B14-O14,0),Q14) -> 171213.47 | S14: =Q14-R14 -> 44411.529 | T14: =MAX(B14-O14-R14,0) -> 0 | U14: =MIN(C14,K14) -> 2526135.8 | V14: =MIN(MAX(C14-U14,0),L14) -> 0 | W14: =MIN(MAX(C14-U14-V14,0),M14) -> 0 | X14: =MAX(K14-U14,0) -> 2.0537659e+08 | Y14: =MAX(L14-V14,0) -> 45000000 | Z14: =MAX(M14-W14,0) -> 13851518 | AA14: =C14-(U14+V14+W14) -> 0 | AB14: =B14-(O14+R14+T14) -> 0 | AC14: =D14-(H14+I14+J14) -> 0
A15: 14 | B15: =LoanPool!L15 -> 1155998 | C15: =LoanPool!M15 -> 2504155.6 | D15: =LoanPool!H15 -> 82434.3 | E15: =X14 -> 2.0537659e+08 | F15: =Y14 -> 45000000 | G15: =Z14 -> 13851518 | H15: =MIN(D15,G15) -> 82434.3 | I15: =MIN(MAX(D15-H15,0),F15) -> 0 | J15: =MIN(MAX(D15-H15-I15,0),E15) -> 0 | K15: =MAX(E15-J15,0) -> 2.0537659e+08 | L15: =MAX(F15-I15,0) -> 45000000 | M15: =MAX(G15-H15,0) -> 13769084 | N15: =K15*Inputs!B6/12 -> 984096.16 | O15: =MIN(B15,N15) -> 984096.16 | P15: =N15-O15 -> 0 | Q15: =L15*Inputs!B6/12 -> 215625 | R15: =MIN(MAX(B15-O15,0),Q15) -> 171901.81 | S15: =Q15-R15 -> 43723.188 | T15: =MAX(B15-O15-R15,0) -> 0 | U15: =MIN(C15,K15) -> 2504155.6 | V15: =MIN(MAX(C15-U15,0),L15) -> 0 | W15: =MIN(MAX(C15-U15-V15,0),M15) -> 0 | X15: =MAX(K15-U15,0) -> 2.0287243e+08 | Y15: =MAX(L15-V15,0) -> 45000000 | Z15: =MAX(M15-W15,0) -> 13769084 | AA15: =C15-(U15+V15+W15) -> 0 | AB15: =B15-(O15+R15+T15) -> 0 | AC15: =D15-(H15+I15+J15) -> 0
A16: 15 | B16: =LoanPool!L16 -> 1144681.6 | C16: =LoanPool!M16 -> 2482359.7 | D16: =LoanPool!H16 -> 81626.475 | E16: =X15 -> 2.0287243e+08 | F16: =Y15 -> 45000000 | G16: =Z15 -> 13769084 | H16: =MIN(D16,G16) -> 81626.475 | I16: =MIN(MAX(D16-H16,0),F16) -> 0 | J16: =MIN(MAX(D16-H16-I16,0),E16) -> 0 | K16: =MAX(E16-J16,0) -> 2.0287243e+08 | L16: =MAX(F16-I16,0) -> 45000000 | M16: =MAX(G16-H16,0) -> 13687457 | N16: =K16*Inputs!B6/12 -> 972097.08 | O16: =MIN(B16,N16) -> 972097.08 | P16: =N16-O16 -> 0 | Q16: =L16*Inputs!B6/12 -> 215625 | R16: =MIN(MAX(B16-O16,0),Q16) -> 172584.56 | S16: =Q16-R16 -> 43040.44 | T16: =MAX(B16-O16-R16,0) -> 0 | U16: =MIN(C16,K16) -> 2482359.7 | V16: =MIN(MAX(C16-U16,0),L16) -> 0 | W16: =MIN(MAX(C16-U16-V16,0),M16) -> 0 | X16: =MAX(K16-U16,0) -> 2.0039007e+08 | Y16: =MAX(L16-V16,0) -> 45000000 | Z16: =MAX(M16-W16,0) -> 13687457 | AA16: =C16-(U16+V16+W16) -> 0 | AB16: =B16-(O16+R16+T16) -> 0 | AC16: =D16-(H16+I16+J16) -> 0
A17: 16 | B17: =LoanPool!L17 -> 1133464.2 | C17: =LoanPool!M17 -> 2460746.4 | D17: =LoanPool!H17 -> 80825.713 | E17: =X16 -> 2.0039007e+08 | F17: =Y16 -> 45000000 | G17: =Z16 -> 13687457 | H17: =MIN(D17,G17) -> 80825.713 | I17: =MIN(MAX(D17-H17,0),F17) -> 0 | J17: =MIN(MAX(D17-H17-I17,0),E17) -> 0 | K17: =MAX(E17-J17,0) -> 2.0039007e+08 | L17: =MAX(F17-I17,0) -> 45000000 | M17: =MAX(G17-H17,0) -> 13606631 | N17: =K17*Inputs!B6/12 -> 960202.44 | O17: =MIN(B17,N17) -> 960202.44 | P17: =N17-O17 -> 0 | Q17: =L17*Inputs!B6/12 -> 215625 | R17: =MIN(MAX(B17-O17,0),Q17) -> 173261.76 | S17: =Q17-R17 -> 42363.24 | T17: =MAX(B17-O17-R17,0) -> 0 | U17: =MIN(C17,K17) -> 2460746.4 | V17: =MIN(MAX(C17-U17,0),L17) -> 0 | W17: =MIN(MAX(C17-U17-V17,0),M17) -> 0 | X17: =MAX(K17-U17,0) -> 1.9792933e+08 | Y17: =MAX(L17-V17,0) -> 45000000 | Z17: =MAX(M17-W17,0) -> 13606631 | AA17: =C17-(U17+V17+W17) -> 0 | AB17: =B17-(O17+R17+T17) -> 0 | AC17: =D17-(H17+I17+J17) -> 0
A18: 17 | B18: =LoanPool!L18 -> 1122344.8 | C18: =LoanPool!M18 -> 2439314.4 | D18: =LoanPool!H18 -> 80031.953 | E18: =X17 -> 1.9792933e+08 | F18: =Y17 -> 45000000 | G18: =Z17 -> 13606631 | H18: =MIN(D18,G18) -> 80031.953 | I18: =MIN(MAX(D18-H18,0),F18) -> 0 | J18: =MIN(MAX(D18-H18-I18,0),E18) -> 0 | K18: =MAX(E18-J18,0) -> 1.9792933e+08 | L18: =MAX(F18-I18,0) -> 45000000 | M18: =MAX(G18-H18,0) -> 13526599 | N18: =K18*Inputs!B6/12 -> 948411.36 | O18: =MIN(B18,N18) -> 948411.36 | P18: =N18-O18 -> 0 | Q18: =L18*Inputs!B6/12 -> 215625 | R18: =MIN(MAX(B18-O18,0),Q18) -> 173933.46 | S18: =Q18-R18 -> 41691.541 | T18: =MAX(B18-O18-R18,0) -> 0 | U18: =MIN(C18,K18) -> 2439314.4 | V18: =MIN(MAX(C18-U18,0),L18) -> 0 | W18: =MIN(MAX(C18-U18-V18,0),M18) -> 0 | X18: =MAX(K18-U18,0) -> 1.9549001e+08 | Y18: =MAX(L18-V18,0) -> 45000000 | Z18: =MAX(M18-W18,0) -> 13526599 | AA18: =C18-(U18+V18+W18) -> 0 | AB18: =B18-(O18+R18+T18) -> 0 | AC18: =D18-(H18+I18+J18) -> 0
A19: 18 | B19: =LoanPool!L19 -> 1111322.7 | C19: =LoanPool!M19 -> 2418062 | D19: =LoanPool!H19 -> 79245.137 | E19: =X18 -> 1.9549001e+08 | F19: =Y18 -> 45000000 | G19: =Z18 -> 13526599 | H19: =MIN(D19,G19) -> 79245.137 | I19: =MIN(MAX(D19-H19,0),F19) -> 0 | J19: =MIN(MAX(D19-H19-I19,0),E19) -> 0 | K19: =MAX(E19-J19,0) -> 1.9549001e+08 | L19: =MAX(F19-I19,0) -> 45000000 | M19: =MAX(G19-H19,0) -> 13447354 | N19: =K19*Inputs!B6/12 -> 936722.98 | O19: =MIN(B19,N19) -> 936722.98 | P19: =N19-O19 -> 0 | Q19: =L19*Inputs!B6/12 -> 215625 | R19: =MIN(MAX(B19-O19,0),Q19) -> 174599.7 | S19: =Q19-R19 -> 41025.3 | T19: =MAX(B19-O19-R19,0) -> 0 | U19: =MIN(C19,K19) -> 2418062 | V19: =MIN(MAX(C19-U19,0),L19) -> 0 | W19: =MIN(MAX(C19-U19-V19,0),M19) -> 0 | X19: =MAX(K19-U19,0) -> 1.9307195e+08 | Y19: =MAX(L19-V19,0) -> 45000000 | Z19: =MAX(M19-W19,0) -> 13447354 | AA19: =C19-(U19+V19+W19) -> 0 | AB19: =B19-(O19+R19+T19) -> 0 | AC19: =D19-(H19+I19+J19) -> 0
A20: 19 | B20: =LoanPool!L20 -> 1100397 | C20: =LoanPool!M20 -> 2396987.9 | D20: =LoanPool!H20 -> 78465.206 | E20: =X19 -> 1.9307195e+08 | F20: =Y19 -> 45000000 | G20: =Z19 -> 13447354 | H20: =MIN(D20,G20) -> 78465.206 | I20: =MIN(MAX(D20-H20,0),F20) -> 0 | J20: =MIN(MAX(D20-H20-I20,0),E20) -> 0 | K20: =MAX(E20-J20,0) -> 1.9307195e+08 | L20: =MAX(F20-I20,0) -> 45000000 | M20: =MAX(G20-H20,0) -> 13368889 | N20: =K20*Inputs!B6/12 -> 925136.44 | O20: =MIN(B20,N20) -> 925136.44 | P20: =N20-O20 -> 0 | Q20: =L20*Inputs!B6/12 -> 215625 | R20: =MIN(MAX(B20-O20,0),Q20) -> 175260.53 | S20: =Q20-R20 -> 40364.471 | T20: =MAX(B20-O20-R20,0) -> 0 | U20: =MIN(C20,K20) -> 2396987.9 | V20: =MIN(MAX(C20-U20,0),L20) -> 0 | W20: =MIN(MAX(C20-U20-V20,0),M20) -> 0 | X20: =MAX(K20-U20,0) -> 1.9067496e+08 | Y20: =MAX(L20-V20,0) -> 45000000 | Z20: =MAX(M20-W20,0) -> 13368889 | AA20: =C20-(U20+V20+W20) -> 0 | AB20: =B20-(O20+R20+T20) -> 0 | AC20: =D20-(H20+I20+J20) -> 0
A21: 20 | B21: =LoanPool!L21 -> 1089566.9 | C21: =LoanPool!M21 -> 2376090.5 | D21: =LoanPool!H21 -> 77692.103 | E21: =X20 -> 1.9067496e+08 | F21: =Y20 -> 45000000 | G21: =Z20 -> 13368889 | H21: =MIN(D21,G21) -> 77692.103 | I21: =MIN(MAX(D21-H21,0),F21) -> 0 | J21: =MIN(MAX(D21-H21-I21,0),E21) -> 0 | K21: =MAX(E21-J21,0) -> 1.9067496e+08 | L21: =MAX(F21-I21,0) -> 45000000 | M21: =MAX(G21-H21,0) -> 13291197 | N21: =K21*Inputs!B6/12 -> 913650.87 | O21: =MIN(B21,N21) -> 913650.87 | P21: =N21-O21 -> 0 | Q21: =L21*Inputs!B6/12 -> 215625 | R21: =MIN(MAX(B21-O21,0),Q21) -> 175915.99 | S21: =Q21-R21 -> 39709.012 | T21: =MAX(B21-O21-R21,0) -> 0 | U21: =MIN(C21,K21) -> 2376090.5 | V21: =MIN(MAX(C21-U21,0),L21) -> 0 | W21: =MIN(MAX(C21-U21-V21,0),M21) -> 0 | X21: =MAX(K21-U21,0) -> 1.8829887e+08 | Y21: =MAX(L21-V21,0) -> 45000000 | Z21: =MAX(M21-W21,0) -> 13291197 | AA21: =C21-(U21+V21+W21) -> 0 | AB21: =B21-(O21+R21+T21) -> 0 | AC21: =D21-(H21+I21+J21) -> 0
A22: 21 | B22: =LoanPool!L22 -> 1078831.6 | C22: =LoanPool!M22 -> 2355368.4 | D22: =LoanPool!H22 -> 76925.77 | E22: =X21 -> 1.8829887e+08 | F22: =Y21 -> 45000000 | G22: =Z21 -> 13291197 | H22: =MIN(D22,G22) -> 76925.77 | I22: =MIN(MAX(D22-H22,0),F22) -> 0 | J22: =MIN(MAX(D22-H22-I22,0),E22) -> 0 | K22: =MAX(E22-J22,0) -> 1.8829887e+08 | L22: =MAX(F22-I22,0) -> 45000000 | M22: =MAX(G22-H22,0) -> 13214271 | N22: =K22*Inputs!B6/12 -> 902265.44 | O22: =MIN(B22,N22) -> 902265.44 | P22: =N22-O22 -> 0 | Q22: =L22*Inputs!B6/12 -> 215625 | R22: =MIN(MAX(B22-O22,0),Q22) -> 176566.12 | S22: =Q22-R22 -> 39058.877 | T22: =MAX(B22-O22-R22,0) -> 0 | U22: =MIN(C22,K22) -> 2355368.4 | V22: =MIN(MAX(C22-U22,0),L22) -> 0 | W22: =MIN(MAX(C22-U22-V22,0),M22) -> 0 | X22: =MAX(K22-U22,0) -> 1.8594351e+08 | Y22: =MAX(L22-V22,0) -> 45000000 | Z22: =MAX(M22-W22,0) -> 13214271 | AA22: =C22-(U22+V22+W22) -> 0 | AB22: =B22-(O22+R22+T22) -> 0 | AC22: =D22-(H22+I22+J22) -> 0
A23: 22 | B23: =LoanPool!L23 -> 1068190.3 | C23: =LoanPool!M23 -> 2334820.1 | D23: =LoanPool!H23 -> 76166.151 | E23: =X22 -> 1.8594351e+08 | F23: =Y22 -> 45000000 | G23: =Z22 -> 13214271 | H23: =MIN(D23,G23) -> 76166.151 | I23: =MIN(MAX(D23-H23,0),F23) -> 0 | J23: =MIN(MAX(D23-H23-I23,0),E23) -> 0 | K23: =MAX(E23-J23,0) -> 1.8594351e+08 | L23: =MAX(F23-I23,0) -> 45000000 | M23: =MAX(G23-H23,0) -> 13138105 | N23: =K23*Inputs!B6/12 -> 890979.3 | O23: =MIN(B23,N23) -> 890979.3 | P23: =N23-O23 -> 0 | Q23: =L23*Inputs!B6/12 -> 215625 | R23: =MIN(MAX(B23-O23,0),Q23) -> 177210.98 | S23: =Q23-R23 -> 38414.024 | T23: =MAX(B23-O23-R23,0) -> 0 | U23: =MIN(C23,K23) -> 2334820.1 | V23: =MIN(MAX(C23-U23,0),L23) -> 0 | W23: =MIN(MAX(C23-U23-V23,0),M23) -> 0 | X23: =MAX(K23-U23,0) -> 1.8360868e+08 | Y23: =MAX(L23-V23,0) -> 45000000 | Z23: =MAX(M23-W23,0) -> 13138105 | AA23: =C23-(U23+V23+W23) -> 0 | AB23: =B23-(O23+R23+T23) -> 0 | AC23: =D23-(H23+I23+J23) -> 0
A24: 23 | B24: =LoanPool!L24 -> 1057642.2 | C24: =LoanPool!M24 -> 2314444.3 | D24: =LoanPool!H24 -> 75413.188 | E24: =X23 -> 1.8360868e+08 | F24: =Y23 -> 45000000 | G24: =Z23 -> 13138105 | H24: =MIN(D24,G24) -> 75413.188 | I24: =MIN(MAX(D24-H24,0),F24) -> 0 | J24: =MIN(MAX(D24-H24-I24,0),E24) -> 0 | K24: =MAX(E24-J24,0) -> 1.8360868e+08 | L24: =MAX(F24-I24,0) -> 45000000 | M24: =MAX(G24-H24,0) -> 13062692 | N24: =K24*Inputs!B6/12 -> 879791.62 | O24: =MIN(B24,N24) -> 879791.62 | P24: =N24-O24 -> 0 | Q24: =L24*Inputs!B6/12 -> 215625 | R24: =MIN(MAX(B24-O24,0),Q24) -> 177850.59 | S24: =Q24-R24 -> 37774.409 | T24: =MAX(B24-O24-R24,0) -> 0 | U24: =MIN(C24,K24) -> 2314444.3 | V24: =MIN(MAX(C24-U24,0),L24) -> 0 | W24: =MIN(MAX(C24-U24-V24,0),M24) -> 0 | X24: =MAX(K24-U24,0) -> 1.8129424e+08 | Y24: =MAX(L24-V24,0) -> 45000000 | Z24: =MAX(M24-W24,0) -> 13062692 | AA24: =C24-(U24+V24+W24) -> 0 | AB24: =B24-(O24+R24+T24) -> 0 | AC24: =D24-(H24+I24+J24) -> 0
A25: 24 | B25: =LoanPool!L25 -> 1047186.6 | C25: =LoanPool!M25 -> 2294239.4 | D25: =LoanPool!H25 -> 74666.827 | E25: =X24 -> 1.8129424e+08 | F25: =Y24 -> 45000000 | G25: =Z24 -> 13062692 | H25: =MIN(D25,G25) -> 74666.827 | I25: =MIN(MAX(D25-H25,0),F25) -> 0 | J25: =MIN(MAX(D25-H25-I25,0),E25) -> 0 | K25: =MAX(E25-J25,0) -> 1.8129424e+08 | L25: =MAX(F25-I25,0) -> 45000000 | M25: =MAX(G25-H25,0) -> 12988025 | N25: =K25*Inputs!B6/12 -> 868701.57 | O25: =MIN(B25,N25) -> 868701.57 | P25: =N25-O25 -> 0 | Q25: =L25*Inputs!B6/12 -> 215625 | R25: =MIN(MAX(B25-O25,0),Q25) -> 178485.01 | S25: =Q25-R25 -> 37139.99 | T25: =MAX(B25-O25-R25,0) -> 0 | U25: =MIN(C25,K25) -> 2294239.4 | V25: =MIN(MAX(C25-U25,0),L25) -> 0 | W25: =MIN(MAX(C25-U25-V25,0),M25) -> 0 | X25: =MAX(K25-U25,0) -> 1.79e+08 | Y25: =MAX(L25-V25,0) -> 45000000 | Z25: =MAX(M25-W25,0) -> 12988025 | AA25: =C25-(U25+V25+W25) -> 0 | AB25: =B25-(O25+R25+T25) -> 0 | AC25: =D25-(H25+I25+J25) -> 0
A26: 25 | B26: =LoanPool!L26 -> 1036822.6 | C26: =LoanPool!M26 -> 2274204 | D26: =LoanPool!H26 -> 73927.011 | E26: =X25 -> 1.79e+08 | F26: =Y25 -> 45000000 | G26: =Z25 -> 12988025 | H26: =MIN(D26,G26) -> 73927.011 | I26: =MIN(MAX(D26-H26,0),F26) -> 0 | J26: =MIN(MAX(D26-H26-I26,0),E26) -> 0 | K26: =MAX(E26-J26,0) -> 1.79e+08 | L26: =MAX(F26-I26,0) -> 45000000 | M26: =MAX(G26-H26,0) -> 12914098 | N26: =K26*Inputs!B6/12 -> 857708.34 | O26: =MIN(B26,N26) -> 857708.34 | P26: =N26-O26 -> 0 | Q26: =L26*Inputs!B6/12 -> 215625 | R26: =MIN(MAX(B26-O26,0),Q26) -> 179114.28 | S26: =Q26-R26 -> 36510.724 | T26: =MAX(B26-O26-R26,0) -> 0 | U26: =MIN(C26,K26) -> 2274204 | V26: =MIN(MAX(C26-U26,0),L26) -> 0 | W26: =MIN(MAX(C26-U26-V26,0),M26) -> 0 | X26: =MAX(K26-U26,0) -> 1.767258e+08 | Y26: =MAX(L26-V26,0) -> 45000000 | Z26: =MAX(M26-W26,0) -> 12914098 | AA26: =C26-(U26+V26+W26) -> 0 | AB26: =B26-(O26+R26+T26) -> 0 | AC26: =D26-(H26+I26+J26) -> 0
A27: 26 | B27: =LoanPool!L27 -> 1026549.5 | C27: =LoanPool!M27 -> 2254336.9 | D27: =LoanPool!H27 -> 73193.686 | E27: =X26 -> 1.767258e+08 | F27: =Y26 -> 45000000 | G27: =Z26 -> 12914098 | H27: =MIN(D27,G27) -> 73193.686 | I27: =MIN(MAX(D27-H27,0),F27) -> 0 | J27: =MIN(MAX(D27-H27-I27,0),E27) -> 0 | K27: =MAX(E27-J27,0) -> 1.767258e+08 | L27: =MAX(F27-I27,0) -> 45000000 | M27: =MAX(G27-H27,0) -> 12840904 | N27: =K27*Inputs!B6/12 -> 846811.11 | O27: =MIN(B27,N27) -> 846811.11 | P27: =N27-O27 -> 0 | Q27: =L27*Inputs!B6/12 -> 215625 | R27: =MIN(MAX(B27-O27,0),Q27) -> 179738.43 | S27: =Q27-R27 -> 35886.57 | T27: =MAX(B27-O27-R27,0) -> 0 | U27: =MIN(C27,K27) -> 2254336.9 | V27: =MIN(MAX(C27-U27,0),L27) -> 0 | W27: =MIN(MAX(C27-U27-V27,0),M27) -> 0 | X27: =MAX(K27-U27,0) -> 1.7447146e+08 | Y27: =MAX(L27-V27,0) -> 45000000 | Z27: =MAX(M27-W27,0) -> 12840904 | AA27: =C27-(U27+V27+W27) -> 0 | AB27: =B27-(O27+R27+T27) -> 0 | AC27: =D27-(H27+I27+J27) -> 0
A28: 27 | B28: =LoanPool!L28 -> 1016366.6 | C28: =LoanPool!M28 -> 2234636.4 | D28: =LoanPool!H28 -> 72466.797 | E28: =X27 -> 1.7447146e+08 | F28: =Y27 -> 45000000 | G28: =Z27 -> 12840904 | H28: =MIN(D28,G28) -> 72466.797 | I28: =MIN(MAX(D28-H28,0),F28) -> 0 | J28: =MIN(MAX(D28-H28-I28,0),E28) -> 0 | K28: =MAX(E28-J28,0) -> 1.7447146e+08 | L28: =MAX(F28-I28,0) -> 45000000 | M28: =MAX(G28-H28,0) -> 12768438 | N28: =K28*Inputs!B6/12 -> 836009.08 | O28: =MIN(B28,N28) -> 836009.08 | P28: =N28-O28 -> 0 | Q28: =L28*Inputs!B6/12 -> 215625 | R28: =MIN(MAX(B28-O28,0),Q28) -> 180357.51 | S28: =Q28-R28 -> 35267.485 | T28: =MAX(B28-O28-R28,0) -> 0 | U28: =MIN(C28,K28) -> 2234636.4 | V28: =MIN(MAX(C28-U28,0),L28) -> 0 | W28: =MIN(MAX(C28-U28-V28,0),M28) -> 0 | X28: =MAX(K28-U28,0) -> 1.7223682e+08 | Y28: =MAX(L28-V28,0) -> 45000000 | Z28: =MAX(M28-W28,0) -> 12768438 | AA28: =C28-(U28+V28+W28) -> 0 | AB28: =B28-(O28+R28+T28) -> 0 | AC28: =D28-(H28+I28+J28) -> 0
A29: 28 | B29: =LoanPool!L29 -> 1006273 | C29: =LoanPool!M29 -> 2215101.4 | D29: =LoanPool!H29 -> 71746.289 | E29: =X28 -> 1.7223682e+08 | F29: =Y28 -> 45000000 | G29: =Z28 -> 12768438 | H29: =MIN(D29,G29) -> 71746.289 | I29: =MIN(MAX(D29-H29,0),F29) -> 0 | J29: =MIN(MAX(D29-H29-I29,0),E29) -> 0 | K29: =MAX(E29-J29,0) -> 1.7223682e+08 | L29: =MAX(F29-I29,0) -> 45000000 | M29: =MAX(G29-H29,0) -> 12696691 | N29: =K29*Inputs!B6/12 -> 825301.45 | O29: =MIN(B29,N29) -> 825301.45 | P29: =N29-O29 -> 0 | Q29: =L29*Inputs!B6/12 -> 215625 | R29: =MIN(MAX(B29-O29,0),Q29) -> 180971.57 | S29: =Q29-R29 -> 34653.429 | T29: =MAX(B29-O29-R29,0) -> 0 | U29: =MIN(C29,K29) -> 2215101.4 | V29: =MIN(MAX(C29-U29,0),L29) -> 0 | W29: =MIN(MAX(C29-U29-V29,0),M29) -> 0 | X29: =MAX(K29-U29,0) -> 1.7002172e+08 | Y29: =MAX(L29-V29,0) -> 45000000 | Z29: =MAX(M29-W29,0) -> 12696691 | AA29: =C29-(U29+V29+W29) -> 0 | AB29: =B29-(O29+R29+T29) -> 0 | AC29: =D29-(H29+I29+J29) -> 0
A30: 29 | B30: =LoanPool!L30 -> 996268.06 | C30: =LoanPool!M30 -> 2195730.5 | D30: =LoanPool!H30 -> 71032.11 | E30: =X29 -> 1.7002172e+08 | F30: =Y29 -> 45000000 | G30: =Z29 -> 12696691 | H30: =MIN(D30,G30) -> 71032.11 | I30: =MIN(MAX(D30-H30,0),F30) -> 0 | J30: =MIN(MAX(D30-H30-I30,0),E30) -> 0 | K30: =MAX(E30-J30,0) -> 1.7002172e+08 | L30: =MAX(F30-I30,0) -> 45000000 | M30: =MAX(G30-H30,0) -> 12625659 | N30: =K30*Inputs!B6/12 -> 814687.42 | O30: =MIN(B30,N30) -> 814687.42 | P30: =N30-O30 -> 0 | Q30: =L30*Inputs!B6/12 -> 215625 | R30: =MIN(MAX(B30-O30,0),Q30) -> 181580.64 | S30: =Q30-R30 -> 34044.36 | T30: =MAX(B30-O30-R30,0) -> 0 | U30: =MIN(C30,K30) -> 2195730.5 | V30: =MIN(MAX(C30-U30,0),L30) -> 0 | W30: =MIN(MAX(C30-U30-V30,0),M30) -> 0 | X30: =MAX(K30-U30,0) -> 1.6782599e+08 | Y30: =MAX(L30-V30,0) -> 45000000 | Z30: =MAX(M30-W30,0) -> 12625659 | AA30: =C30-(U30+V30+W30) -> 0 | AB30: =B30-(O30+R30+T30) -> 0 | AC30: =D30-(H30+I30+J30) -> 0
A31: 30 | B31: =LoanPool!L31 -> 986350.97 | C31: =LoanPool!M31 -> 2176522.1 | D31: =LoanPool!H31 -> 70324.205 | E31: =X30 -> 1.6782599e+08 | F31: =Y30 -> 45000000 | G31: =Z30 -> 12625659 | H31: =MIN(D31,G31) -> 70324.205 | I31: =MIN(MAX(D31-H31,0),F31) -> 0 | J31: =MIN(MAX(D31-H31-I31,0),E31) -> 0 | K31: =MAX(E31-J31,0) -> 1.6782599e+08 | L31: =MAX(F31-I31,0) -> 45000000 | M31: =MAX(G31-H31,0) -> 12555335 | N31: =K31*Inputs!B6/12 -> 804166.21 | O31: =MIN(B31,N31) -> 804166.21 | P31: =N31-O31 -> 0 | Q31: =L31*Inputs!B6/12 -> 215625 | R31: =MIN(MAX(B31-O31,0),Q31) -> 182184.76 | S31: =Q31-R31 -> 33440.238 | T31: =MAX(B31-O31-R31,0) -> 0 | U31: =MIN(C31,K31) -> 2176522.1 | V31: =MIN(MAX(C31-U31,0),L31) -> 0 | W31: =MIN(MAX(C31-U31-V31,0),M31) -> 0 | X31: =MAX(K31-U31,0) -> 1.6564947e+08 | Y31: =MAX(L31-V31,0) -> 45000000 | Z31: =MAX(M31-W31,0) -> 12555335 | AA31: =C31-(U31+V31+W31) -> 0 | AB31: =B31-(O31+R31+T31) -> 0 | AC31: =D31-(H31+I31+J31) -> 0
A32: 31 | B32: =LoanPool!L32 -> 976521.02 | C32: =LoanPool!M32 -> 2157475.1 | D32: =LoanPool!H32 -> 69622.523 | E32: =X31 -> 1.6564947e+08 | F32: =Y31 -> 45000000 | G32: =Z31 -> 12555335 | H32: =MIN(D32,G32) -> 69622.523 | I32: =MIN(MAX(D32-H32,0),F32) -> 0 | J32: =MIN(MAX(D32-H32-I32,0),E32) -> 0 | K32: =MAX(E32-J32,0) -> 1.6564947e+08 | L32: =MAX(F32-I32,0) -> 45000000 | M32: =MAX(G32-H32,0) -> 12485712 | N32: =K32*Inputs!B6/12 -> 793737.04 | O32: =MIN(B32,N32) -> 793737.04 | P32: =N32-O32 -> 0 | Q32: =L32*Inputs!B6/12 -> 215625 | R32: =MIN(MAX(B32-O32,0),Q32) -> 182783.98 | S32: =Q32-R32 -> 32841.022 | T32: =MAX(B32-O32-R32,0) -> 0 | U32: =MIN(C32,K32) -> 2157475.1 | V32: =MIN(MAX(C32-U32,0),L32) -> 0 | W32: =MIN(MAX(C32-U32-V32,0),M32) -> 0 | X32: =MAX(K32-U32,0) -> 1.6349199e+08 | Y32: =MAX(L32-V32,0) -> 45000000 | Z32: =MAX(M32-W32,0) -> 12485712 | AA32: =C32-(U32+V32+W32) -> 0 | AB32: =B32-(O32+R32+T32) -> 0 | AC32: =D32-(H32+I32+J32) -> 0
A33: 32 | B33: =LoanPool!L33 -> 966777.47 | C33: =LoanPool!M33 -> 2138588.2 | D33: =LoanPool!H33 -> 68927.01 | E33: =X32 -> 1.6349199e+08 | F33: =Y32 -> 45000000 | G33: =Z32 -> 12485712 | H33: =MIN(D33,G33) -> 68927.01 | I33: =MIN(MAX(D33-H33,0),F33) -> 0 | J33: =MIN(MAX(D33-H33-I33,0),E33) -> 0 | K33: =MAX(E33-J33,0) -> 1.6349199e+08 | L33: =MAX(F33-I33,0) -> 45000000 | M33: =MAX(G33-H33,0) -> 12416785 | N33: =K33*Inputs!B6/12 -> 783399.14 | O33: =MIN(B33,N33) -> 783399.14 | P33: =N33-O33 -> 0 | Q33: =L33*Inputs!B6/12 -> 215625 | R33: =MIN(MAX(B33-O33,0),Q33) -> 183378.33 | S33: =Q33-R33 -> 32246.673 | T33: =MAX(B33-O33-R33,0) -> 0 | U33: =MIN(C33,K33) -> 2138588.2 | V33: =MIN(MAX(C33-U33,0),L33) -> 0 | W33: =MIN(MAX(C33-U33-V33,0),M33) -> 0 | X33: =MAX(K33-U33,0) -> 1.6135341e+08 | Y33: =MAX(L33-V33,0) -> 45000000 | Z33: =MAX(M33-W33,0) -> 12416785 | AA33: =C33-(U33+V33+W33) -> 0 | AB33: =B33-(O33+R33+T33) -> 0 | AC33: =D33-(H33+I33+J33) -> 0
A34: 33 | B34: =LoanPool!L34 -> 957119.59 | C34: =LoanPool!M34 -> 2119859.8 | D34: =LoanPool!H34 -> 68237.615 | E34: =X33 -> 1.6135341e+08 | F34: =Y33 -> 45000000 | G34: =Z33 -> 12416785 | H34: =MIN(D34,G34) -> 68237.615 | I34: =MIN(MAX(D34-H34,0),F34) -> 0 | J34: =MIN(MAX(D34-H34-I34,0),E34) -> 0 | K34: =MAX(E34-J34,0) -> 1.6135341e+08 | L34: =MAX(F34-I34,0) -> 45000000 | M34: =MAX(G34-H34,0) -> 12348548 | N34: =K34*Inputs!B6/12 -> 773151.74 | O34: =MIN(B34,N34) -> 773151.74 | P34: =N34-O34 -> 0 | Q34: =L34*Inputs!B6/12 -> 215625 | R34: =MIN(MAX(B34-O34,0),Q34) -> 183967.85 | S34: =Q34-R34 -> 31657.15 | T34: =MAX(B34-O34-R34,0) -> 0 | U34: =MIN(C34,K34) -> 2119859.8 | V34: =MIN(MAX(C34-U34,0),L34) -> 0 | W34: =MIN(MAX(C34-U34-V34,0),M34) -> 0 | X34: =MAX(K34-U34,0) -> 1.5923355e+08 | Y34: =MAX(L34-V34,0) -> 45000000 | Z34: =MAX(M34-W34,0) -> 12348548 | AA34: =C34-(U34+V34+W34) -> 0 | AB34: =B34-(O34+R34+T34) -> 0 | AC34: =D34-(H34+I34+J34) -> 0
A35: 34 | B35: =LoanPool!L35 -> 947546.66 | C35: =LoanPool!M35 -> 2101288.9 | D35: =LoanPool!H35 -> 67554.287 | E35: =X34 -> 1.5923355e+08 | F35: =Y34 -> 45000000 | G35: =Z34 -> 12348548 | H35: =MIN(D35,G35) -> 67554.287 | I35: =MIN(MAX(D35-H35,0),F35) -> 0 | J35: =MIN(MAX(D35-H35-I35,0),E35) -> 0 | K35: =MAX(E35-J35,0) -> 1.5923355e+08 | L35: =MAX(F35-I35,0) -> 45000000 | M35: =MAX(G35-H35,0) -> 12280994 | N35: =K35*Inputs!B6/12 -> 762994.08 | O35: =MIN(B35,N35) -> 762994.08 | P35: =N35-O35 -> 0 | Q35: =L35*Inputs!B6/12 -> 215625 | R35: =MIN(MAX(B35-O35,0),Q35) -> 184552.59 | S35: =Q35-R35 -> 31072.414 | T35: =MAX(B35-O35-R35,0) -> 0 | U35: =MIN(C35,K35) -> 2101288.9 | V35: =MIN(MAX(C35-U35,0),L35) -> 0 | W35: =MIN(MAX(C35-U35-V35,0),M35) -> 0 | X35: =MAX(K35-U35,0) -> 1.5713226e+08 | Y35: =MAX(L35-V35,0) -> 45000000 | Z35: =MAX(M35-W35,0) -> 12280994 | AA35: =C35-(U35+V35+W35) -> 0 | AB35: =B35-(O35+R35+T35) -> 0 | AC35: =D35-(H35+I35+J35) -> 0
A36: 35 | B36: =LoanPool!L36 -> 938057.98 | C36: =LoanPool!M36 -> 2082873.9 | D36: =LoanPool!H36 -> 66876.974 | E36: =X35 -> 1.5713226e+08 | F36: =Y35 -> 45000000 | G36: =Z35 -> 12280994 | H36: =MIN(D36,G36) -> 66876.974 | I36: =MIN(MAX(D36-H36,0),F36) -> 0 | J36: =MIN(MAX(D36-H36-I36,0),E36) -> 0 | K36: =MAX(E36-J36,0) -> 1.5713226e+08 | L36: =MAX(F36-I36,0) -> 45000000 | M36: =MAX(G36-H36,0) -> 12214117 | N36: =K36*Inputs!B6/12 -> 752925.4 | O36: =MIN(B36,N36) -> 752925.4 | P36: =N36-O36 -> 0 | Q36: =L36*Inputs!B6/12 -> 215625 | R36: =MIN(MAX(B36-O36,0),Q36) -> 185132.57 | S36: =Q36-R36 -> 30492.427 | T36: =MAX(B36-O36-R36,0) -> 0 | U36: =MIN(C36,K36) -> 2082873.9 | V36: =MIN(MAX(C36-U36,0),L36) -> 0 | W36: =MIN(MAX(C36-U36-V36,0),M36) -> 0 | X36: =MAX(K36-U36,0) -> 1.5504938e+08 | Y36: =MAX(L36-V36,0) -> 45000000 | Z36: =MAX(M36-W36,0) -> 12214117 | AA36: =C36-(U36+V36+W36) -> 0 | AB36: =B36-(O36+R36+T36) -> 0 | AC36: =D36-(H36+I36+J36) -> 0
A37: 36 | B37: =LoanPool!L37 -> 928652.82 | C37: =LoanPool!M37 -> 2064613.8 | D37: =LoanPool!H37 -> 66205.626 | E37: =X36 -> 1.5504938e+08 | F37: =Y36 -> 45000000 | G37: =Z36 -> 12214117 | H37: =MIN(D37,G37) -> 66205.626 | I37: =MIN(MAX(D37-H37,0),F37) -> 0 | J37: =MIN(MAX(D37-H37-I37,0),E37) -> 0 | K37: =MAX(E37-J37,0) -> 1.5504938e+08 | L37: =MAX(F37-I37,0) -> 45000000 | M37: =MAX(G37-H37,0) -> 12147911 | N37: =K37*Inputs!B6/12 -> 742944.97 | O37: =MIN(B37,N37) -> 742944.97 | P37: =N37-O37 -> 0 | Q37: =L37*Inputs!B6/12 -> 215625 | R37: =MIN(MAX(B37-O37,0),Q37) -> 185707.85 | S37: =Q37-R37 -> 29917.15 | T37: =MAX(B37-O37-R37,0) -> 0 | U37: =MIN(C37,K37) -> 2064613.8 | V37: =MIN(MAX(C37-U37,0),L37) -> 0 | W37: =MIN(MAX(C37-U37-V37,0),M37) -> 0 | X37: =MAX(K37-U37,0) -> 1.5298477e+08 | Y37: =MAX(L37-V37,0) -> 45000000 | Z37: =MAX(M37-W37,0) -> 12147911 | AA37: =C37-(U37+V37+W37) -> 0 | AB37: =B37-(O37+R37+T37) -> 0 | AC37: =D37-(H37+I37+J37) -> 0
A38: 37 | B38: =LoanPool!L38 -> 919330.48 | C38: =LoanPool!M38 -> 2046507.1 | D38: =LoanPool!H38 -> 65540.192 | E38: =X37 -> 1.5298477e+08 | F38: =Y37 -> 45000000 | G38: =Z37 -> 12147911 | H38: =MIN(D38,G38) -> 65540.192 | I38: =MIN(MAX(D38-H38,0),F38) -> 0 | J38: =MIN(MAX(D38-H38-I38,0),E38) -> 0 | K38: =MAX(E38-J38,0) -> 1.5298477e+08 | L38: =MAX(F38-I38,0) -> 45000000 | M38: =MAX(G38-H38,0) -> 12082371 | N38: =K38*Inputs!B6/12 -> 733052.02 | O38: =MIN(B38,N38) -> 733052.02 | P38: =N38-O38 -> 0 | Q38: =L38*Inputs!B6/12 -> 215625 | R38: =MIN(MAX(B38-O38,0),Q38) -> 186278.46 | S38: =Q38-R38 -> 29346.544 | T38: =MAX(B38-O38-R38,0) -> 0 | U38: =MIN(C38,K38) -> 2046507.1 | V38: =MIN(MAX(C38-U38,0),L38) -> 0 | W38: =MIN(MAX(C38-U38-V38,0),M38) -> 0 | X38: =MAX(K38-U38,0) -> 1.5093826e+08 | Y38: =MAX(L38-V38,0) -> 45000000 | Z38: =MAX(M38-W38,0) -> 12082371 | AA38: =C38-(U38+V38+W38) -> 0 | AB38: =B38-(O38+R38+T38) -> 0 | AC38: =D38-(H38+I38+J38) -> 0
A39: 38 | B39: =LoanPool!L39 -> 910090.27 | C39: =LoanPool!M39 -> 2028552.7 | D39: =LoanPool!H39 -> 64880.622 | E39: =X38 -> 1.5093826e+08 | F39: =Y38 -> 45000000 | G39: =Z38 -> 12082371 | H39: =MIN(D39,G39) -> 64880.622 | I39: =MIN(MAX(D39-H39,0),F39) -> 0 | J39: =MIN(MAX(D39-H39-I39,0),E39) -> 0 | K39: =MAX(E39-J39,0) -> 1.5093826e+08 | L39: =MAX(F39-I39,0) -> 45000000 | M39: =MAX(G39-H39,0) -> 12017490 | N39: =K39*Inputs!B6/12 -> 723245.84 | O39: =MIN(B39,N39) -> 723245.84 | P39: =N39-O39 -> 0 | Q39: =L39*Inputs!B6/12 -> 215625 | R39: =MIN(MAX(B39-O39,0),Q39) -> 186844.43 | S39: =Q39-R39 -> 28780.571 | T39: =MAX(B39-O39-R39,0) -> 0 | U39: =MIN(C39,K39) -> 2028552.7 | V39: =MIN(MAX(C39-U39,0),L39) -> 0 | W39: =MIN(MAX(C39-U39-V39,0),M39) -> 0 | X39: =MAX(K39-U39,0) -> 1.4890971e+08 | Y39: =MAX(L39-V39,0) -> 45000000 | Z39: =MAX(M39-W39,0) -> 12017490 | AA39: =C39-(U39+V39+W39) -> 0 | AB39: =B39-(O39+R39+T39) -> 0 | AC39: =D39-(H39+I39+J39) -> 0
A40: 39 | B40: =LoanPool!L40 -> 900931.5 | C40: =LoanPool!M40 -> 2010749.2 | D40: =LoanPool!H40 -> 64226.868 | E40: =X39 -> 1.4890971e+08 | F40: =Y39 -> 45000000 | G40: =Z39 -> 12017490 | H40: =MIN(D40,G40) -> 64226.868 | I40: =MIN(MAX(D40-H40,0),F40) -> 0 | J40: =MIN(MAX(D40-H40-I40,0),E40) -> 0 | K40: =MAX(E40-J40,0) -> 1.4890971e+08 | L40: =MAX(F40-I40,0) -> 45000000 | M40: =MAX(G40-H40,0) -> 11953263 | N40: =K40*Inputs!B6/12 -> 713525.7 | O40: =MIN(B40,N40) -> 713525.7 | P40: =N40-O40 -> 0 | Q40: =L40*Inputs!B6/12 -> 215625 | R40: =MIN(MAX(B40-O40,0),Q40) -> 187405.81 | S40: =Q40-R40 -> 28219.193 | T40: =MAX(B40-O40-R40,0) -> 0 | U40: =MIN(C40,K40) -> 2010749.2 | V40: =MIN(MAX(C40-U40,0),L40) -> 0 | W40: =MIN(MAX(C40-U40-V40,0),M40) -> 0 | X40: =MAX(K40-U40,0) -> 1.4689896e+08 | Y40: =MAX(L40-V40,0) -> 45000000 | Z40: =MAX(M40-W40,0) -> 11953263 | AA40: =C40-(U40+V40+W40) -> 0 | AB40: =B40-(O40+R40+T40) -> 0 | AC40: =D40-(H40+I40+J40) -> 0
